Workbook

Sheet Matcher
A1: Knullrunkcupen 2025/2026
A2: Matcher | H2: Blå | I2: Mål | J2: Assist | M2: Rosa | N2: Mål | O2: Assist | R2: Grön | S2: Mål | T2: Assist | W2: Brun | AB2: Målvakter | AD2: Mål | AE2: Assist
A3: Hemma | B3: Resultat | E3: Borta | F3: Vinnare | G3: Förlorare | H3: Spelare | I3: Mål | J3: Assist | K3: Vinster | L3: Förluster | M3: Spelare | N3: Mål | O3: Assist | P3: Vinster | Q3: Förluster | R3: Spelare | S3: Mål | T3: Assist | U3: Vinster | V3: Förluster | W3: Spelare | X3: Mål | Y3: Assist | AB3: Spelare | AD3: Mål | AE3: Assist | AF3: Vinster | AG3: Förluster | AH3: Nollor | AK3: Nollor H | AL3: Nollor B
A4: Gameweek 1 | H4: =A4 -> Gameweek 1 | K4: Vin. | L4: För. | M4: Gameweek 1 | P4: Vin. | Q4: För. | R4: =A4 -> Gameweek 1 | U4: Vin. | V4: För. | W4: =A4 -> Gameweek 1 | Z4: Vin. | AA4: För. | AB4: =A4 -> Gameweek 1 | AF4: Vin. | AG4: För. | AH4: Nollor | AI4: Temp
A5: Blå | B5: 0 | C5: =IF(ISBLANK(A5), "", "-") -> - | D5: 1 | E5: Rosa | F5: =IF(AND(B5 <> "", D5 <> ""), IF(B5 > D5, A5, IF(D5 > B5, E5, "Oavgjort")), "") -> Rosa | G5: =IF(AND(B5 <> "", D5 <> ""), IF(B5 < D5, A5, IF(D5 < B5, E5, "Oavgjort")), "") -> Blå | H5: Samuel P | I5: 2 | J5: 0 | K5: {=IF(SEQUENCE(18, 1), COUNTIF(F5:F22, $H$2))} -> 4 | L5: {=IF(SEQUENCE(18, 1), COUNTIF(G5:G22, $H$2))} -> 5 | M5: Daniel K | N5: 0 | O5: 1 | P5: {=IF(SEQUENCE(18, 1), COUNTIF(F5:F22, $M$2))} -> 5 | Q5: {=IF(SEQUENCE(18, 1), COUNTIF(G5:G22, $M$2))} -> 4 | R5: Yvan I | S5: 0 | T5: 0 | U5: {=IF(SEQUENCE(18, 1), COUNTIF(F5:F22, $R$2))} -> 0 | V5: {=IF(SEQUENCE(18, 1), COUNTIF(G5:G22, $R$2))} -> 0 | X5: 0 | Y5: 0 | Z5: {=IF(SEQUENCE(18, 1), COUNTIF(F5:F22, $W$2))} -> 0 | AA5: {=IF(SEQUENCE(18, 1), COUNTIF(G5:G22, $W$2))} -> 0 | AB5: Hemma | AC5: Branislav D | AD5: 0 | AE5: 1 | AF5: =IF(AB5 = "Borta", AJ5, (IF(AB5 = "Hemma", AI5, 0))) -> 4 | AG5: 5 | AH5: =IF(AB5 = "Borta", AK5, (IF(AB5 = "Hemma", AL5, 0))) -> 3 | AI5: {=IF(F5 <> "", SEQUENCE(18,1,1,0)*SUM(IF(A5:A22 = F5:F22, 1, 0)), SEQUENCE(18,1,0,0) )} -> 4 | AJ5: {=IF(G5 <> "", SEQUENCE(18,1,1,0)*SUM(IF(E5:E22 = F5:F22, 1, 0)), SEQUENCE(18,1,0,0) )} -> 9 | AK5: {=IF(SEQUENCE(18, 1), COUNTIF(B5:B22, 0))} -> 7 | AL5: {=IF(SEQUENCE(18, 1), COUNTIF(D5:D22, 0))} -> 3
A6: Blå | B6: 0 | C6: =IF(ISBLANK(A6), "", "-") -> - | D6: 2 | E6: Rosa | F6: =IF(AND(B6 <> "", D6 <> ""), IF(B6 > D6, A6, IF(D6 > B6, E6, "Oavgjort")), "") -> Rosa | G6: =IF(AND(B6 <> "", D6 <> ""), IF(B6 < D6, A6, IF(D6 < B6, E6, "Oavgjort")), "") -> Blå | H6: Albert A | I6: 0 | J6: 0 | K6: 4 | L6: 5 | M6: Shahir I | N6: 0 | O6: 0 | P6: 5 | Q6: 4 | S6: 0 | T6: 0 | U6: 0 | V6: 0 | X6: 0 | Y6: 0 | Z6: 0 | AA6: 0 | AB6: Borta | AC6: Emil B | AD6: 0 | AE6: 0 | AF6: 5 | AG6: =IF(AB6 = "Hemma", AJ6, (IF(AB6 = "Borta", AI6, 0))) -> 4 | AH6: =IF(AB6 = "Borta", AK6, (IF(AB6 = "Hemma", AL6, 0))) -> 7 | AI6: 4 | AJ6: 9 | AK6: 7 | AL6: 3
A7: Blå | B7: 0 | C7: =IF(ISBLANK(A7), "", "-") -> - | D7: 0 | E7: Rosa | F7: =IF(AND(B7 <> "", D7 <> ""), IF(B7 > D7, A7, IF(D7 > B7, E7, "Oavgjort")), "") -> Oavgjort | G7: =IF(AND(B7 <> "", D7 <> ""), IF(B7 < D7, A7, IF(D7 < B7, E7, "Oavgjort")), "") -> Oavgjort | H7: Amiin M | I7: 3 | J7: 3 | K7: 4 | L7: 5 | M7: Milos G | N7: 5 | O7: 3 | P7: 5 | Q7: 4 | S7: 0 | T7: 0 | U7: 0 | V7: 0 | X7: 0 | Y7: 0 | Z7: 0 | AA7: 0 | AF7: =IF(AB7 = "Borta", AJ7, (IF(AB7 = "Hemma", AI7, 0))) -> 0 | AG7: =IF(AB7 = "Hemma", AJ7, (IF(AB7 = "Borta", AI7, 0))) -> 0 | AH7: =IF(AB7 = "Borta", AK7, (IF(AB7 = "Hemma", AL7, 0))) -> 0 | AI7: 4 | AJ7: 9 | AK7: 7 | AL7: 3
A8: Blå | B8: 0 | C8: =IF(ISBLANK(A8), "", "-") -> - | D8: 2 | E8: Rosa | F8: =IF(AND(B8 <> "", D8 <> ""), IF(B8 > D8, A8, IF(D8 > B8, E8, "Oavgjort")), "") -> Rosa | G8: =IF(AND(B8 <> "", D8 <> ""), IF(B8 < D8, A8, IF(D8 < B8, E8, "Oavgjort")), "") -> Blå | H8: Aria A | I8: 0 | J8: 1 | K8: 4 | L8: 5 | M8: Oskar R | N8: 2 | O8: 1 | P8: 5 | Q8: 4 | S8: 0 | T8: 0 | U8: 0 | V8: 0 | X8: 0 | Y8: 0 | Z8: 0 | AA8: 0 | AF8: =IF(AB8 = "Borta", AJ8, (IF(AB8 = "Hemma", AI8, 0))) -> 0 | AG8: =IF(AB8 = "Hemma", AJ8, (IF(AB8 = "Borta", AI8, 0))) -> 0 | AH8: =IF(AB8 = "Borta", AK8, (IF(AB8 = "Hemma", AL8, 0))) -> 0 | AI8: 4 | AJ8: 9 | AK8: 7 | AL8: 3
A9: Rosa | B9: 1 | C9: =IF(ISBLANK(A9), "", "-") -> - | D9: 0 | E9: Blå | F9: =IF(AND(B9 <> "", D9 <> ""), IF(B9 > D9, A9, IF(D9 > B9, E9, "Oavgjort")), "") -> Rosa | G9: =IF(AND(B9 <> "", D9 <> ""), IF(B9 < D9, A9, IF(D9 < B9, E9, "Oavgjort")), "") -> Blå | H9: Oliver G | I9: 0 | J9: 0 | K9: 4 | L9: 5 | M9: Jakob S | N9: 2 | O9: 3 | P9: 5 | Q9: 4 | S9: 0 | T9: 0 | U9: 0 | V9: 0 | X9: 0 | Y9: 0 | Z9: 0 | AA9: 0 | AF9: =IF(AB9 = "Borta", AJ9, (IF(AB9 = "Hemma", AI9, 0))) -> 0 | AG9: =IF(AB9 = "Hemma", AJ9, (IF(AB9 = "Borta", AI9, 0))) -> 0 | AH9: =IF(AB9 = "Borta", AK9, (IF(AB9 = "Hemma", AL9, 0))) -> 0 | AI9: 4 | AJ9: 9 | AK9: 7 | AL9: 3
A10: Rosa | B10: 1 | C10: =IF(ISBLANK(A10), "", "-") -> - | D10: 3 | E10: Blå | F10: =IF(AND(B10 <> "", D10 <> ""), IF(B10 > D10, A10, IF(D10 > B10, E10, "Oavgjort")), "") -> Blå | G10: =IF(AND(B10 <> "", D10 <> ""), IF(B10 < D10, A10, IF(D10 < B10, E10, "Oavgjort")), "") -> Rosa | H10: Oskar B | I10: 2 | J10: 2 | K10: 4 | L10: 5 | P10: 5 | Q10: 4 | U10: 0 | V10: 0 | Z10: 0 | AA10: 0 | AF10: =IF(AB10 = "Borta", AJ10, (IF(AB10 = "Hemma", AI10, 0))) -> 0 | AG10: =IF(AB10 = "Hemma", AJ10, (IF(AB10 = "Borta", AI10, 0))) -> 0 | AH10: =IF(AB10 = "Borta", AK10, (IF(AB10 = "Hemma", AL10, 0))) -> 0 | AI10: 4 | AJ10: 9 | AK10: 7 | AL10: 3
A11: Rosa | B11: 0 | C11: =IF(ISBLANK(A11), "", "-") -> - | D11: 1 | E11: Blå | F11: =IF(AND(B11 <> "", D11 <> ""), IF(B11 > D11, A11, IF(D11 > B11, E11, "Oavgjort")), "") -> Blå | G11: =IF(AND(B11 <> "", D11 <> ""), IF(B11 < D11, A11, IF(D11 < B11, E11, "Oavgjort")), "") -> Rosa | K11: 4 | L11: 5 | P11: 5 | Q11: 4 | U11: 0 | V11: 0 | Z11: 0 | AA11: 0 | AF11: =IF(AB11 = "Borta", AJ11, (IF(AB11 = "Hemma", AI11, 0))) -> 0 | AG11: =IF(AB11 = "Hemma", AJ11, (IF(AB11 = "Borta", AI11, 0))) -> 0 | AH11: =IF(AB11 = "Borta", AK11, (IF(AB11 = "Hemma", AL11, 0))) -> 0 | AI11: 4 | AJ11: 9 | AK11: 7 | AL11: 3
A12: Rosa | B12: 0 | C12: =IF(ISBLANK(A12), "", "-") -> - | D12: 1 | E12: Blå | F12: =IF(AND(B12 <> "", D12 <> ""), IF(B12 > D12, A12, IF(D12 > B12, E12, "Oavgjort")), "") -> Blå | G12: =IF(AND(B12 <> "", D12 <> ""), IF(B12 < D12, A12, IF(D12 < B12, E12, "Oavgjort")), "") -> Rosa | K12: 4 | L12: 5 | P12: 5 | Q12: 4 | U12: 0 | V12: 0 | Z12: 0 | AA12: 0 | AF12: =IF(AB12 = "Borta", AJ12, (IF(AB12 = "Hemma", AI12, 0))) -> 0 | AG12: =IF(AB12 = "Hemma", AJ12, (IF(AB12 = "Borta", AI12, 0))) -> 0 | AH12: =IF(AB12 = "Borta", AK12, (IF(AB12 = "Hemma", AL12, 0))) -> 0 | AI12: 4 | AJ12: 9 | AK12: 7 | AL12: 3
A13: Blå | B13: 0 | C13: =IF(ISBLANK(A13), "", "-") -> - | D13: 1 | E13: Rosa | F13: =IF(AND(B13 <> "", D13 <> ""), IF(B13 > D13, A13, IF(D13 > B13, E13, "Oavgjort")), "") -> Rosa | G13: =IF(AND(B13 <> "", D13 <> ""), IF(B13 < D13, A13, IF(D13 < B13, E13, "Oavgjort")), "") -> Blå | K13: 4 | L13: 5 | P13: 5 | Q13: 4 | U13: 0 | V13: 0 | Z13: 0 | AA13: 0 | AF13: =IF(AB13 = "Borta", AJ13, (IF(AB13 = "Hemma", AI13, 0))) -> 0 | AG13: =IF(AB13 = "Hemma", AJ13, (IF(AB13 = "Borta", AI13, 0))) -> 0 | AH13: =IF(AB13 = "Borta", AK13, (IF(AB13 = "Hemma", AL13, 0))) -> 0 | AI13: 4 | AJ13: 9 | AK13: 7 | AL13: 3
A14: Blå | B14: 2 | C14: =IF(ISBLANK(A14), "", "-") -> - | D14: 0 | E14: Rosa | F14: =IF(AND(B14 <> "", D14 <> ""), IF(B14 > D14, A14, IF(D14 > B14, E14, "Oavgjort")), "") -> Blå | G14: =IF(AND(B14 <> "", D14 <> ""), IF(B14 < D14, A14, IF(D14 < B14, E14, "Oavgjort")), "") -> Rosa | K14: 4 | L14: 5 | P14: 5 | Q14: 4 | U14: 0 | V14: 0 | Z14: 0 | AA14: 0 | AF14: =IF(AB14 = "Borta", AJ14, (IF(AB14 = "Hemma", AI14, 0))) -> 0 | AG14: =IF(AB14 = "Hemma", AJ14, (IF(AB14 = "Borta", AI14, 0))) -> 0 | AH14: =IF(AB14 = "Borta", AK14, (IF(AB14 = "Hemma", AL14, 0))) -> 0 | AI14: 4 | AJ14: 9 | AK14: 7 | AL14: 3
A15: Blå | C15: =IF(ISBLANK(A15), "", "-") -> - | E15: Rosa | F15: =IF(AND(B15 <> "", D15 <> ""), IF(B15 > D15, A15, IF(D15 > B15, E15, "Oavgjort")), "") | G15: =IF(AND(B15 <> "", D15 <> ""), IF(B15 < D15, A15, IF(D15 < B15, E15, "Oavgjort")), "") | K15: 4 | L15: 5 | P15: 5 | Q15: 4 | U15: 0 | V15: 0 | Z15: 0 | AA15: 0 | AF15: =IF(AB15 = "Borta", AJ15, (IF(AB15 = "Hemma", AI15, 0))) -> 0 | AG15: =IF(AB15 = "Hemma", AJ15, (IF(AB15 = "Borta", AI15, 0))) -> 0 | AH15: =IF(AB15 = "Borta", AK15, (IF(AB15 = "Hemma", AL15, 0))) -> 0 | AI15: 4 | AJ15: 9 | AK15: 7 | AL15: 3
A16: Blå | C16: =IF(ISBLANK(A16), "", "-") -> - | E16: Rosa | F16: =IF(AND(B16 <> "", D16 <> ""), IF(B16 > D16, A16, IF(D16 > B16, E16, "Oavgjort")), "") | G16: =IF(AND(B16 <> "", D16 <> ""), IF(B16 < D16, A16, IF(D16 < B16, E16, "Oavgjort")), "") | K16: 4 | L16: 5 | P16: 5 | Q16: 4 | U16: 0 | V16: 0 | Z16: 0 | AA16: 0 | AF16: =IF(AB16 = "Borta", AJ16, (IF(AB16 = "Hemma", AI16, 0))) -> 0 | AG16: =IF(AB16 = "Hemma", AJ16, (IF(AB16 = "Borta", AI16, 0))) -> 0 | AH16: =IF(AB16 = "Borta", AK16, (IF(AB16 = "Hemma", AL16, 0))) -> 0 | AI16: 4 | AJ16: 9 | AK16: 7 | AL16: 3
A17: Rosa | C17: =IF(ISBLANK(A17), "", "-") -> - | E17: Blå | F17: =IF(AND(B17 <> "", D17 <> ""), IF(B17 > D17, A17, IF(D17 > B17, E17, "Oavgjort")), "") | G17: =IF(AND(B17 <> "", D17 <> ""), IF(B17 < D17, A17, IF(D17 < B17, E17, "Oavgjort")), "") | K17: 4 | L17: 5 | P17: 5 | Q17: 4 | U17: 0 | V17: 0 | Z17: 0 | AA17: 0 | AF17: =IF(AB17 = "Borta", AJ17, (IF(AB17 = "Hemma", AI17, 0))) -> 0 | AG17: =IF(AB17 = "Hemma", AJ17, (IF(AB17 = "Borta", AI17, 0))) -> 0 | AH17: =IF(AB17 = "Borta", AK17, (IF(AB17 = "Hemma", AL17, 0))) -> 0 | AI17: 4 | AJ17: 9 | AK17: 7 | AL17: 3
A18: Rosa | C18: =IF(ISBLANK(A18), "", "-") -> - | E18: Blå | F18: =IF(AND(B18 <> "", D18 <> ""), IF(B18 > D18, A18, IF(D18 > B18, E18, "Oavgjort")), "") | G18: =IF(AND(B18 <> "", D18 <> ""), IF(B18 < D18, A18, IF(D18 < B18, E18, "Oavgjort")), "") | K18: 4 | L18: 5 | P18: 5 | Q18: 4 | U18: 0 | V18: 0 | Z18: 0 | AA18: 0 | AF18: =IF(AB18 = "Borta", AJ18, (IF(AB18 = "Hemma", AI18, 0))) -> 0 | AG18: =IF(AB18 = "Hemma", AJ18, (IF(AB18 = "Borta", AI18, 0))) -> 0 | AH18: =IF(AB18 = "Borta", AK18, (IF(AB18 = "Hemma", AL18, 0))) -> 0 | AI18: 4 | AJ18: 9 | AK18: 7 | AL18: 3
A19: Rosa | C19: =IF(ISBLANK(A19), "", "-") -> - | E19: Blå | F19: =IF(AND(B19 <> "", D19 <> ""), IF(B19 > D19, A19, IF(D19 > B19, E19, "Oavgjort")), "") | G19: =IF(AND(B19 <> "", D19 <> ""), IF(B19 < D19, A19, IF(D19 < B19, E19, "Oavgjort")), "") | K19: 4 | L19: 5 | P19: 5 | Q19: 4 | U19: 0 | V19: 0 | Z19: 0 | AA19: 0 | AF19: =IF(AB19 = "Borta", AJ19, (IF(AB19 = "Hemma", AI19, 0))) -> 0 | AG19: =IF(AB19 = "Hemma", AJ19, (IF(AB19 = "Borta", AI19, 0))) -> 0 | AH19: =IF(AB19 = "Borta", AK19, (IF(AB19 = "Hemma", AL19, 0))) -> 0 | AI19: 4 | AJ19: 9 | AK19: 7 | AL19: 3
A20: Rosa | C20: =IF(ISBLANK(A20), "", "-") -> - | E20: Blå | F20: =IF(AND(B20 <> "", D20 <> ""), IF(B20 > D20, A20, IF(D20 > B20, E20, "Oavgjort")), "") | G20: =IF(AND(B20 <> "", D20 <> ""), IF(B20 < D20, A20, IF(D20 < B20, E20, "Oavgjort")), "") | K20: 4 | L20: 5 | P20: 5 | Q20: 4 | U20: 0 | V20: 0 | Z20: 0 | AA20: 0 | AF20: =IF(AB20 = "Borta", AJ20, (IF(AB20 = "Hemma", AI20, 0))) -> 0 | AG20: =IF(AB20 = "Hemma", AJ20, (IF(AB20 = "Borta", AI20, 0))) -> 0 | AH20: =IF(AB20 = "Borta", AK20, (IF(AB20 = "Hemma", AL20, 0))) -> 0 | AI20: 4 | AJ20: 9 | AK20: 7 | AL20: 3
C21: =IF(ISBLANK(A21), "", "-") | F21: =IF(AND(B21 <> "", D21 <> ""), IF(B21 > D21, A21, IF(D21 > B21, E21, "Oavgjort")), "") | G21: =IF(AND(B21 <> "", D21 <> ""), IF(B21 < D21, A21, IF(D21 < B21, E21, "Oavgjort")), "") | K21: 4 | L21: 5 | P21: 5 | Q21: 4 | U21: 0 | V21: 0 | Z21: 0 | AA21: 0 | AF21: =IF(AB21 = "Borta", AJ21, (IF(AB21 = "Hemma", AI21, 0))) -> 0 | AG21: =IF(AB21 = "Hemma", AJ21, (IF(AB21 = "Borta", AI21, 0))) -> 0 | AH21: =IF(AB21 = "Borta", AK21, (IF(AB21 = "Hemma", AL21, 0))) -> 0 | AI21: 4 | AJ21: 9 | AK21: 7 | AL21: 3
C22: =IF(ISBLANK(A22), "", "-") | F22: =IF(AND(B22 <> "", D22 <> ""), IF(B22 > D22, A22, IF(D22 > B22, E22, "Oavgjort")), "") | G22: =IF(AND(B22 <> "", D22 <> ""), IF(B22 < D22, A22, IF(D22 < B22, E22, "Oavgjort")), "") | K22: 4 | L22: 5 | P22: 5 | Q22: 4 | U22: 0 | V22: 0 | Z22: 0 | AA22: 0 | AF22: =IF(AB22 = "Borta", AJ22, (IF(AB22 = "Hemma", AI22, 0))) -> 0 | AG22: =IF(AB22 = "Hemma", AJ22, (IF(AB22 = "Borta", AI22, 0))) -> 0 | AH22: =IF(AB22 = "Borta", AK22, (IF(AB22 = "Hemma", AL22, 0))) -> 0 | AI22: 4 | AJ22: 9 | AK22: 7 | AL22: 3
A24: =IFERROR(__xludf.DUMMYFUNCTION("""Gameweek "" & (VALUE(REGEXEXTRACT(A4, ""Gameweek (\d+)"")) + 1)"),"Gameweek 2") -> Gameweek 2 | H24: =A24 -> Gameweek 2 | K24: Vin. | L24: För. | M24: =A24 -> Gameweek 2 | P24: Vin. | Q24: För. | R24: =A24 -> Gameweek 2 | U24: Vin. | V24: För. | W24: =A24 -> Gameweek 2 | Z24: Vin. | AA24: För. | AB24: =A24 -> Gameweek 2 | AF24: Vin. | AG24: För. | AH24: Nollor | AI24: Temp
A25: Blå | B25: 0 | C25: =IF(ISBLANK(A25), "", "-") -> - | D25: 1 | E25: Rosa | F25: =IF(AND(B25 <> "", D25 <> ""), IF(B25 > D25, A25, IF(D25 > B25, E25, "Oavgjort")), "") -> Rosa | G25: =IF(AND(B25 <> "", D25 <> ""), IF(B25 < D25, A25, IF(D25 < B25, E25, "Oavgjort")), "") -> Blå | H25: Samuel P | I25: 1 | J25: 4 | K25: {=IF(SEQUENCE(18, 1), COUNTIF(F25:F42, $H$2))} -> 1 | L25: {=IF(SEQUENCE(18, 1), COUNTIF(G25:G42, $H$2))} -> 5 | M25: Branislav D | N25: 5 | O25: 2 | P25: {=IF(SEQUENCE(18, 1), COUNTIF(F25:F42, $M$2))} -> 5 | Q25: {=IF(SEQUENCE(18, 1), COUNTIF(G25:G42, $M$2))} -> 1 | R25: Aria A | S25: 0 | T25: 0 | U25: {=IF(SEQUENCE(18, 1), COUNTIF(F25:F42, $R$2))} -> 0 | V25: {=IF(SEQUENCE(18, 1), COUNTIF(G25:G42, $R$2))} -> 0 | X25: 0 | Y25: 0 | Z25: {=IF(SEQUENCE(18, 1), COUNTIF(F25:F42, $W$2))} -> 0 | AA25: {=IF(SEQUENCE(18, 1), COUNTIF(G25:G42, $W$2))} -> 0 | AB25: Hemma | AC25: Einar D | AD25: 0 | AE25: 0 | AF25: 1 | AG25: =IF(AB25 = "Hemma", AJ25, (IF(AB25 = "Borta", AI25, 0))) -> 5 | AH25: =IF(AB25 = "Borta", AK25, (IF(AB25 = "Hemma", AL25, 0))) -> 4 | AI25: {=IF(F25 <> "", SEQUENCE(18,1,1,0)*SUM(IF(A25:A42 = F25:F42, 1, 0)), SEQUENCE(18,1,0,0) )} -> 5 | AJ25: {=IF(G25 <> "", SEQUENCE(18,1,1,0)*SUM(IF(E25:E42 = F25:F42, 1, 0)), SEQUENCE(18,1,0,0) )} -> 5 | AK25: {=IF(SEQUENCE(18, 1), COUNTIF(B25:B42, 0))} -> 4 | AL25: {=IF(SEQUENCE(18, 1), COUNTIF(D25:D42, 0))} -> 4
A26: Blå | B26: 0 | C26: =IF(ISBLANK(A26), "", "-") -> - | D26: 0 | E26: Rosa | F26: =IF(AND(B26 <> "", D26 <> ""), IF(B26 > D26, A26, IF(D26 > B26, E26, "Oavgjort")), "") -> Oavgjort | G26: =IF(AND(B26 <> "", D26 <> ""), IF(B26 < D26, A26, IF(D26 < B26, E26, "Oavgjort")), "") -> Oavgjort | H26: Emil F | I26: 4 | J26: 0 | K26: 1 | L26: 5 | M26: Oliver G | N26: 3 | O26: 3 | P26: 5 | Q26: 1 | R26: Pontus S | S26: 0 | T26: 0 | U26: 0 | V26: 0 | X26: 0 | Y26: 0 | Z26: 0 | AA26: 0 | AB26: Borta | AC26: Emil B | AD26: 1 | AE26: 1 | AF26: =IF(AB26 = "Borta", AJ26, (IF(AB26 = "Hemma", AI26, 0))) -> 5 | AG26: 1 | AH26: =IF(AB26 = "Borta", AK26, (IF(AB26 = "Hemma", AL26, 0))) -> 4 | AI26: 5 | AJ26: 5 | AK26: 4 | AL26: 4
A27: Blå | B27: 0 | C27: =IF(ISBLANK(A27), "", "-") -> - | D27: 1 | E27: Rosa | F27: =IF(AND(B27 <> "", D27 <> ""), IF(B27 > D27, A27, IF(D27 > B27, E27, "Oavgjort")), "") -> Rosa | G27: =IF(AND(B27 <> "", D27 <> ""), IF(B27 < D27, A27, IF(D27 < B27, E27, "Oavgjort")), "") -> Blå | H27: Isak L | I27: 0 | J27: 1 | K27: 1 | L27: 5 | M27: Oskar R | N27: 1 | O27: 2 | P27: 5 | Q27: 1 | R27: Jesper N | S27: 0 | T27: 0 | U27: 0 | V27: 0 | X27: 0 | Y27: 0 | Z27: 0 | AA27: 0 | AF27: =IF(AB27 = "Borta", AJ27, (IF(AB27 = "Hemma", AI27, 0))) -> 0 | AG27: =IF(AB27 = "Hemma", AJ27, (IF(AB27 = "Borta", AI27, 0))) -> 0 | AH27: =IF(AB27 = "Borta", AK27, (IF(AB27 = "Hemma", AL27, 0))) -> 0 | AI27: 5 | AJ27: 5 | AK27: 4 | AL27: 4
A28: Blå | B28: 1 | C28: =IF(ISBLANK(A28), "", "-") -> - | D28: 2 | E28: Rosa | F28: =IF(AND(B28 <> "", D28 <> ""), IF(B28 > D28, A28, IF(D28 > B28, E28, "Oavgjort")), "") -> Rosa | G28: =IF(AND(B28 <> "", D28 <> ""), IF(B28 < D28, A28, IF(D28 < B28, E28, "Oavgjort")), "") -> Blå | H28: Daniel K | I28: 0 | J28: 0 | K28: 1 | L28: 5 | M28: Magnus D | N28: 1 | O28: 3 | P28: 5 | Q28: 1 | S28: 0 | T28: 0 | U28: 0 | V28: 0 | X28: 0 | Y28: 0 | Z28: 0 | AA28: 0 | AF28: =IF(AB28 = "Borta", AJ28, (IF(AB28 = "Hemma", AI28, 0))) -> 0 | AG28: =IF(AB28 = "Hemma", AJ28, (IF(AB28 = "Borta", AI28, 0))) -> 0 | AH28: =IF(AB28 = "Borta", AK28, (IF(AB28 = "Hemma", AL28, 0))) -> 0 | AI28: 5 | AJ28: 5 | AK28: 4 | AL28: 4
A29: Rosa | B29: 0 | C29: =IF(ISBLANK(A29), "", "-") -> - | D29: 0 | E29: Blå | F29: =IF(AND(B29 <> "", D29 <> ""), IF(B29 > D29, A29, IF(D29 > B29, E29, "Oavgjort")), "") -> Oavgjort | G29: =IF(AND(B29 <> "", D29 <> ""), IF(B29 < D29, A29, IF(D29 < B29, E29, "Oavgjort")), "") -> Oavgjort | H29: Jakob S | I29: 1 | J29: 1 | K29: 1 | L29: 5 | N29: 0 | O29: 0 | P29: 5 | Q29: 1 | S29: 0 | T29: 0 | U29: 0 | V29: 0 | X29: 0 | Y29: 0 | Z29: 0 | AA29: 0 | AF29: =IF(AB29 = "Borta", AJ29, (IF(AB29 = "Hemma", AI29, 0))) -> 0 | AG29: =IF(AB29 = "Hemma", AJ29, (IF(AB29 = "Borta", AI29, 0))) -> 0 | AH29: =IF(AB29 = "Borta", AK29, (IF(AB29 = "Hemma", AL29, 0))) -> 0 | AI29: 5 | AJ29: 5 | AK29: 4 | AL29: 4
A30: Rosa | B30: 2 | C30: =IF(ISBLANK(A30), "", "-") -> - | D30: 0 | E30: Blå | F30: =IF(AND(B30 <> "", D30 <> ""), IF(B30 > D30, A30, IF(D30 > B30, E30, "Oavgjort")), "") -> Rosa | G30: =IF(AND(B30 <> "", D30 <> ""), IF(B30 < D30, A30, IF(D30 < B30, E30, "Oavgjort")), "") -> Blå | I30: 0 | J30: 0 | K30: 1 | L30: 5 | N30: 0 | O30: 0 | P30: 5 | Q30: 1 | S30: 0 | T30: 0 | U30: 0 | V30: 0 | X30: 0 | Y30: 0 | Z30: 0 | AA30: 0 | AF30: =IF(AB30 = "Borta", AJ30, (IF(AB30 = "Hemma", AI30, 0))) -> 0 | AG30: =IF(AB30 = "Hemma", AJ30, (IF(AB30 = "Borta", AI30, 0))) -> 0 | AH30: =IF(AB30 = "Borta", AK30, (IF(AB30 = "Hemma", AL30, 0))) -> 0 | AI30: 5 | AJ30: 5 | AK30: 4 | AL30: 4
A31: Rosa | B31: 3 | C31: =IF(ISBLANK(A31), "", "-") -> - | D31: 0 | E31: Blå | F31: =IF(AND(B31 <> "", D31 <> ""), IF(B31 > D31, A31, IF(D31 > B31, E31, "Oavgjort")), "") -> Rosa | G31: =IF(AND(B31 <> "", D31 <> ""), IF(B31 < D31, A31, IF(D31 < B31, E31, "Oavgjort")), "") -> Blå | I31: 0 | J31: 0 | K31: 1 | L31: 5 | N31: 0 | O31: 0 | P31: 5 | Q31: 1 | S31: 0 | T31: 0 | U31: 0 | V31: 0 | X31: 0 | Y31: 0 | Z31: 0 | AA31: 0 | AF31: =IF(AB31 = "Borta", AJ31, (IF(AB31 = "Hemma", AI31, 0))) -> 0 | AG31: =IF(AB31 = "Hemma", AJ31, (IF(AB31 = "Borta", AI31, 0))) -> 0 | AH31: =IF(AB31 = "Borta", AK31, (IF(AB31 = "Hemma", AL31, 0))) -> 0 | AI31: 5 | AJ31: 5 | AK31: 4 | AL31: 4
A32: Rosa | B32: 2 | C32: =IF(ISBLANK(A32), "", "-") -> - | D32: 2 | E32: Blå | F32: =IF(AND(B32 <> "", D32 <> ""), IF(B32 > D32, A32, IF(D32 > B32, E32, "Oavgjort")), "") -> Oavgjort | G32: =IF(AND(B32 <> "", D32 <> ""), IF(B32 < D32, A32, IF(D32 < B32, E32, "Oavgjort")), "") -> Oavgjort | K32: 1 | L32: 5 | P32: 5 | Q32: 1 | U32: 0 | V32: 0 | Z32: 0 | AA32: 0 | AF32: =IF(AB32 = "Borta", AJ32, (IF(AB32 = "Hemma", AI32, 0))) -> 0 | AG32: =IF(AB32 = "Hemma", AJ32, (IF(AB32 = "Borta", AI32, 0))) -> 0 | AH32: =IF(AB32 = "Borta", AK32, (IF(AB32 = "Hemma", AL32, 0))) -> 0 | AI32: 5 | AJ32: 5 | AK32: 4 | AL32: 4
A33: Blå | B33: 1 | C33: =IF(ISBLANK(A33), "", "-") -> - | D33: 1 | E33: Rosa | F33: =IF(AND(B33 <> "", D33 <> ""), IF(B33 > D33, A33, IF(D33 > B33, E33, "Oavgjort")), "") -> Oavgjort | G33: =IF(AND(B33 <> "", D33 <> ""), IF(B33 < D33, A33, IF(D33 < B33, E33, "Oavgjort")), "") -> Oavgjort | K33: 1 | L33: 5 | P33: 5 | Q33: 1 | U33: 0 | V33: 0 | Z33: 0 | AA33: 0 | AF33: =IF(AB33 = "Borta", AJ33, (IF(AB33 = "Hemma", AI33, 0))) -> 0 | AG33: =IF(AB33 = "Hemma", AJ33, (IF(AB33 = "Borta", AI33, 0))) -> 0 | AH33: =IF(AB33 = "Borta", AK33, (IF(AB33 = "Hemma", AL33, 0))) -> 0 | AI33: 5 | AJ33: 5 | AK33: 4 | AL33: 4
A34: Blå | B34: 2 | C34: =IF(ISBLANK(A34), "", "-") -> - | D34: 1 | E34: Rosa | F34: =IF(AND(B34 <> "", D34 <> ""), IF(B34 > D34, A34, IF(D34 > B34, E34, "Oavgjort")), "") -> Blå | G34: =IF(AND(B34 <> "", D34 <> ""), IF(B34 < D34, A34, IF(D34 < B34, E34, "Oavgjort")), "") -> Rosa | K34: 1 | L34: 5 | P34: 5 | Q34: 1 | U34: 0 | V34: 0 | Z34: 0 | AA34: 0 | AF34: =IF(AB34 = "Borta", AJ34, (IF(AB34 = "Hemma", AI34, 0))) -> 0 | AG34: =IF(AB34 = "Hemma", AJ34, (IF(AB34 = "Borta", AI34, 0))) -> 0 | AH34: =IF(AB34 = "Borta", AK34, (IF(AB34 = "Hemma", AL34, 0))) -> 0 | AI34: 5 | AJ34: 5 | AK34: 4 | AL34: 4
A35: Blå | C35: =IF(ISBLANK(A35), "", "-") -> - | E35: Rosa | F35: =IF(AND(B35 <> "", D35 <> ""), IF(B35 > D35, A35, IF(D35 > B35, E35, "Oavgjort")), "") | G35: =IF(AND(B35 <> "", D35 <> ""), IF(B35 < D35, A35, IF(D35 < B35, E35, "Oavgjort")), "") | K35: 1 | L35: 5 | P35: 5 | Q35: 1 | U35: 0 | V35: 0 | Z35: 0 | AA35: 0 | AF35: =IF(AB35 = "Borta", AJ35, (IF(AB35 = "Hemma", AI35, 0))) -> 0 | AG35: =IF(AB35 = "Hemma", AJ35, (IF(AB35 = "Borta", AI35, 0))) -> 0 | AH35: =IF(AB35 = "Borta", AK35, (IF(AB35 = "Hemma", AL35, 0))) -> 0 | AI35: 5 | AJ35: 5 | AK35: 4 | AL35: 4
A36: Blå | C36: =IF(ISBLANK(A36), "", "-") -> - | E36: Rosa | F36: =IF(AND(B36 <> "", D36 <> ""), IF(B36 > D36, A36, IF(D36 > B36, E36, "Oavgjort")), "") | G36: =IF(AND(B36 <> "", D36 <> ""), IF(B36 < D36, A36, IF(D36 < B36, E36, "Oavgjort")), "") | K36: 1 | L36: 5 | P36: 5 | Q36: 1 | U36: 0 | V36: 0 | Z36: 0 | AA36: 0 | AF36: =IF(AB36 = "Borta", AJ36, (IF(AB36 = "Hemma", AI36, 0))) -> 0 | AG36: =IF(AB36 = "Hemma", AJ36, (IF(AB36 = "Borta", AI36, 0))) -> 0 | AH36: =IF(AB36 = "Borta", AK36, (IF(AB36 = "Hemma", AL36, 0))) -> 0 | AI36: 5 | AJ36: 5 | AK36: 4 | AL36: 4
A37: Rosa | C37: =IF(ISBLANK(A37), "", "-") -> - | E37: Blå | F37: =IF(AND(B37 <> "", D37 <> ""), IF(B37 > D37, A37, IF(D37 > B37, E37, "Oavgjort")), "") | G37: =IF(AND(B37 <> "", D37 <> ""), IF(B37 < D37, A37, IF(D37 < B37, E37, "Oavgjort")), "") | K37: 1 | L37: 5 | P37: 5 | Q37: 1 | U37: 0 | V37: 0 | Z37: 0 | AA37: 0 | AF37: =IF(AB37 = "Borta", AJ37, (IF(AB37 = "Hemma", AI37, 0))) -> 0 | AG37: =IF(AB37 = "Hemma", AJ37, (IF(AB37 = "Borta", AI37, 0))) -> 0 | AH37: =IF(AB37 = "Borta", AK37, (IF(AB37 = "Hemma", AL37, 0))) -> 0 | AI37: 5 | AJ37: 5 | AK37: 4 | AL37: 4
A38: Rosa | C38: =IF(ISBLANK(A38), "", "-") -> - | E38: Blå | F38: =IF(AND(B38 <> "", D38 <> ""), IF(B38 > D38, A38, IF(D38 > B38, E38, "Oavgjort")), "") | G38: =IF(AND(B38 <> "", D38 <> ""), IF(B38 < D38, A38, IF(D38 < B38, E38, "Oavgjort")), "") | K38: 1 | L38: 5 | P38: 5 | Q38: 1 | U38: 0 | V38: 0 | Z38: 0 | AA38: 0 | AF38: =IF(AB38 = "Borta", AJ38, (IF(AB38 = "Hemma", AI38, 0))) -> 0 | AG38: =IF(AB38 = "Hemma", AJ38, (IF(AB38 = "Borta", AI38, 0))) -> 0 | AH38: =IF(AB38 = "Borta", AK38, (IF(AB38 = "Hemma", AL38, 0))) -> 0 | AI38: 5 | AJ38: 5 | AK38: 4 | AL38: 4
A39: Rosa | C39: =IF(ISBLANK(A39), "", "-") -> - | E39: Blå | F39: =IF(AND(B39 <> "", D39 <> ""), IF(B39 > D39, A39, IF(D39 > B39, E39, "Oavgjort")), "") | G39: =IF(AND(B39 <> "", D39 <> ""), IF(B39 < D39, A39, IF(D39 < B39, E39, "Oavgjort")), "") | K39: 1 | L39: 5 | P39: 5 | Q39: 1 | U39: 0 | V39: 0 | Z39: 0 | AA39: 0 | AF39: =IF(AB39 = "Borta", AJ39, (IF(AB39 = "Hemma", AI39, 0))) -> 0 | AG39: =IF(AB39 = "Hemma", AJ39, (IF(AB39 = "Borta", AI39, 0))) -> 0 | AH39: =IF(AB39 = "Borta", AK39, (IF(AB39 = "Hemma", AL39, 0))) -> 0 | AI39: 5 | AJ39: 5 | AK39: 4 | AL39: 4
A40: Rosa | C40: =IF(ISBLANK(A40), "", "-") -> - | E40: Blå | F40: =IF(AND(B40 <> "", D40 <> ""), IF(B40 > D40, A40, IF(D40 > B40, E40, "Oavgjort")), "") | G40: =IF(AND(B40 <> "", D40 <> ""), IF(B40 < D40, A40, IF(D40 < B40, E40, "Oavgjort")), "") | K40: 1 | L40: 5 | P40: 5 | Q40: 1 | U40: 0 | V40: 0 | Z40: 0 | AA40: 0 | AF40: =IF(AB40 = "Borta", AJ40, (IF(AB40 = "Hemma", AI40, 0))) -> 0 | AG40: =IF(AB40 = "Hemma", AJ40, (IF(AB40 = "Borta", AI40, 0))) -> 0 | AH40: =IF(AB40 = "Borta", AK40, (IF(AB40 = "Hemma", AL40, 0))) -> 0 | AI40: 5 | AJ40: 5 | AK40: 4 | AL40: 4
C41: =IF(ISBLANK(A41), "", "-") | F41: =IF(AND(B41 <> "", D41 <> ""), IF(B41 > D41, A41, IF(D41 > B41, E41, "Oavgjort")), "") | G41: =IF(AND(B41 <> "", D41 <> ""), IF(B41 < D41, A41, IF(D41 < B41, E41, "Oavgjort")), "") | K41: 1 | L41: 5 | P41: 5 | Q41: 1 | U41: 0 | V41: 0 | Z41: 0 | AA41: 0 | AF41: =IF(AB41 = "Borta", AJ41, (IF(AB41 = "Hemma", AI41, 0))) -> 0 | AG41: =IF(AB41 = "Hemma", AJ41, (IF(AB41 = "Borta", AI41, 0))) -> 0 | AH41: =IF(AB41 = "Borta", AK41, (IF(AB41 = "Hemma", AL41, 0))) -> 0 | AI41: 5 | AJ41: 5 | AK41: 4 | AL41: 4
...

Sheet Poängligan
A1: Namn | B1: Mål | C1: Assist | D1: Vinster | E1: Förluster | F1: Närvaro | G1: Nollor | H1: Resultat | J1: PPT | K1: Rating | L1: Namn | M1: Mål | N1: Assist | O1: Vinster | P1: Förluster | Q1: Närvaro | R1: Nollor | S1: Resultat
A2: =IFERROR(__xludf.DUMMYFUNCTION("QUERY(L2:S179, ""SELECT * WHERE L IS NOT NULL ORDER BY S DESC"") "),"Jakob S") -> Jakob S | B2: =IFERROR(__xludf.DUMMYFUNCTION("""COMPUTED_VALUE"""),36.0) -> 36 | C2: =IFERROR(__xludf.DUMMYFUNCTION("""COMPUTED_VALUE"""),37.0) -> 37 | D2: =IFERROR(__xludf.DUMMYFUNCTION("""COMPUTED_VALUE"""),52.0) -> 52 | E2: =IFERROR(__xludf.DUMMYFUNCTION("""COMPUTED_VALUE"""),32.0) -> 32 | F2: =IFERROR(__xludf.DUMMYFUNCTION("""COMPUTED_VALUE"""),15.0) -> 15 | G2: =IFERROR(__xludf.DUMMYFUNCTION("""COMPUTED_VALUE"""),0.0) -> 0 | H2: =IFERROR(__xludf.DUMMYFUNCTION("""COMPUTED_VALUE"""),174.0) -> 174 | I2: =IF(H2 <> "", REPT("▮", ROUND((H2 / $H$2) * 30,0)) & REPT("▯", 30 - ROUND((H2 / $H$2) * 30,0)), "") -> ▮▮▮▮▮▮▮▮▮▮▮▮▮▮▮▮▮▮▮▮▮▮▮▮▮▮▮▮▮▮ | J2: =IFERROR(ROUND(H2/F2, 1), "") -> 11.6 | K2: =IFERROR(ROUND(MIN(99, 94 * (0.8*MIN(1, J2/J$2) + 0.2*H2/H$2)),0), "") -> 94 | L2: {=SORT(UNIQUE(Spelarstatistik!A2:A179))} -> Achillie X | M2: =SUMIF(Spelarstatistik!A$2:A179, L2, Spelarstatistik!B$2:B179) -> 0 | N2: =SUMIF(Spelarstatistik!A$2:A179, L2, Spelarstatistik!C$2:C179) -> 0 | O2: =SUMIF(Spelarstatistik!A$2:A179, L2, Spelarstatistik!D$2:D179) -> 1 | P2: =SUMIF(Spelarstatistik!A$2:A179, L2, Spelarstatistik!E$2:E179) -> 3 | Q2: =COUNTIF(Spelarstatistik!A$2:A179, L2) -> 1 | R2: =SUMIF(Matcher!AC$5:AC179, L2, Matcher!AH$5:AH179) -> 0 | S2: =IF(L2 <> "", ROUND(M2 + N2 + 0.5 * O2 + 5 * Q2 + 0.5 * R2,0), "") -> 6
A3: =IFERROR(__xludf.DUMMYFUNCTION("""COMPUTED_VALUE"""),"Oliver G") -> Oliver G | B3: =IFERROR(__xludf.DUMMYFUNCTION("""COMPUTED_VALUE"""),28.0) -> 28 | C3: =IFERROR(__xludf.DUMMYFUNCTION("""COMPUTED_VALUE"""),22.0) -> 22 | D3: =IFERROR(__xludf.DUMMYFUNCTION("""COMPUTED_VALUE"""),48.0) -> 48 | E3: =IFERROR(__xludf.DUMMYFUNCTION("""COMPUTED_VALUE"""),50.0) -> 50 | F3: =IFERROR(__xludf.DUMMYFUNCTION("""COMPUTED_VALUE"""),17.0) -> 17 | G3: =IFERROR(__xludf.DUMMYFUNCTION("""COMPUTED_VALUE"""),0.0) -> 0 | H3: =IFERROR(__xludf.DUMMYFUNCTION("""COMPUTED_VALUE"""),159.0) -> 159 | I3: =IF(H3 <> "", REPT("▮", ROUND((H3 / $H$2) * 30,0)) & REPT("▯", 30 - ROUND((H3 / $H$2) * 30,0)), "") -> ▮▮▮▮▮▮▮▮▮▮▮▮▮▮▮▮▮▮▮▮▮▮▮▮▮▮▮▯▯▯ | J3: =IFERROR(ROUND(H3/F3, 1), "") -> 9.4 | K3: =IFERROR(ROUND(MIN(99, 94 * (0.8*MIN(1, J3/J$2) + 0.2*H3/H$2)),0), "") -> 78 | L3: Albert A | M3: =SUMIF(Spelarstatistik!A$2:A179, L3, Spelarstatistik!B$2:B179) -> 3 | N3: =SUMIF(Spelarstatistik!A$2:A179, L3, Spelarstatistik!C$2:C179) -> 2 | O3: =SUMIF(Spelarstatistik!A$2:A179, L3, Spelarstatistik!D$2:D179) -> 13 | P3: =SUMIF(Spelarstatistik!A$2:A179, L3, Spelarstatistik!E$2:E179) -> 19 | Q3: =COUNTIF(Spelarstatistik!A$2:A179, L3) -> 6 | R3: =SUMIF(Matcher!AC$5:AC179, L3, Matcher!AH$5:AH179) -> 0 | S3: =IF(L3 <> "", ROUND(M3 + N3 + 0.5 * O3 + 5 * Q3 + 0.5 * R3,0), "") -> 42
A4: =IFERROR(__xludf.DUMMYFUNCTION("""COMPUTED_VALUE"""),"Emil B") -> Emil B | B4: =IFERROR(__xludf.DUMMYFUNCTION("""COMPUTED_VALUE"""),3.0) -> 3 | C4: =IFERROR(__xludf.DUMMYFUNCTION("""COMPUTED_VALUE"""),9.0) -> 9 | D4: =IFERROR(__xludf.DUMMYFUNCTION("""COMPUTED_VALUE"""),56.0) -> 56 | E4: =IFERROR(__xludf.DUMMYFUNCTION("""COMPUTED_VALUE"""),57.0) -> 57 | F4: =IFERROR(__xludf.DUMMYFUNCTION("""COMPUTED_VALUE"""),14.0) -> 14 | G4: =IFERROR(__xludf.DUMMYFUNCTION("""COMPUTED_VALUE"""),72.0) -> 72 | H4: =IFERROR(__xludf.DUMMYFUNCTION("""COMPUTED_VALUE"""),146.0) -> 146 | I4: =IF(H4 <> "", REPT("▮", ROUND((H4 / $H$2) * 30,0)) & REPT("▯", 30 - ROUND((H4 / $H$2) * 30,0)), "") -> ▮▮▮▮▮▮▮▮▮▮▮▮▮▮▮▮▮▮▮▮▮▮▮▮▮▯▯▯▯▯ | J4: =IFERROR(ROUND(H4/F4, 1), "") -> 10.4 | K4: =IFERROR(ROUND(MIN(99, 94 * (0.8*MIN(1, J4/J$2) + 0.2*H4/H$2)),0), "") -> 83 | L4: Amiin M | M4: =SUMIF(Spelarstatistik!A$2:A179, L4, Spelarstatistik!B$2:B179) -> 3 | N4: =SUMIF(Spelarstatistik!A$2:A179, L4, Spelarstatistik!C$2:C179) -> 3 | O4: =SUMIF(Spelarstatistik!A$2:A179, L4, Spelarstatistik!D$2:D179) -> 4 | P4: =SUMIF(Spelarstatistik!A$2:A179, L4, Spelarstatistik!E$2:E179) -> 5 | Q4: =COUNTIF(Spelarstatistik!A$2:A179, L4) -> 1 | R4: =SUMIF(Matcher!AC$5:AC179, L4, Matcher!AH$5:AH179) -> 0 | S4: =IF(L4 <> "", ROUND(M4 + N4 + 0.5 * O4 + 5 * Q4 + 0.5 * R4,0), "") -> 13
A5: =IFERROR(__xludf.DUMMYFUNCTION("""COMPUTED_VALUE"""),"Daniel K") -> Daniel K | B5: =IFERROR(__xludf.DUMMYFUNCTION("""COMPUTED_VALUE"""),24.0) -> 24 | C5: =IFERROR(__xludf.DUMMYFUNCTION("""COMPUTED_VALUE"""),20.0) -> 20 | D5: =IFERROR(__xludf.DUMMYFUNCTION("""COMPUTED_VALUE"""),37.0) -> 37 | E5: =IFERROR(__xludf.DUMMYFUNCTION("""COMPUTED_VALUE"""),36.0) -> 36 | F5: =IFERROR(__xludf.DUMMYFUNCTION("""COMPUTED_VALUE"""),14.0) -> 14 | G5: =IFERROR(__xludf.DUMMYFUNCTION("""COMPUTED_VALUE"""),0.0) -> 0 | H5: =IFERROR(__xludf.DUMMYFUNCTION("""COMPUTED_VALUE"""),133.0) -> 133 | I5: =IF(H5 <> "", REPT("▮", ROUND((H5 / $H$2) * 30,0)) & REPT("▯", 30 - ROUND((H5 / $H$2) * 30,0)), "") -> ▮▮▮▮▮▮▮▮▮▮▮▮▮▮▮▮▮▮▮▮▮▮▮▯▯▯▯▯▯▯ | J5: =IFERROR(ROUND(H5/F5, 1), "") -> 9.5 | K5: =IFERROR(ROUND(MIN(99, 94 * (0.8*MIN(1, J5/J$2) + 0.2*H5/H$2)),0), "") -> 76 | L5: Aria A | M5: =SUMIF(Spelarstatistik!A$2:A179, L5, Spelarstatistik!B$2:B179) -> 11 | N5: =SUMIF(Spelarstatistik!A$2:A179, L5, Spelarstatistik!C$2:C179) -> 15 | O5: =SUMIF(Spelarstatistik!A$2:A179, L5, Spelarstatistik!D$2:D179) -> 33 | P5: =SUMIF(Spelarstatistik!A$2:A179, L5, Spelarstatistik!E$2:E179) -> 22 | Q5: =COUNTIF(Spelarstatistik!A$2:A179, L5) -> 13 | R5: =SUMIF(Matcher!AC$5:AC179, L5, Matcher!AH$5:AH179) -> 0 | S5: =IF(L5 <> "", ROUND(M5 + N5 + 0.5 * O5 + 5 * Q5 + 0.5 * R5,0), "") -> 108
A6: =IFERROR(__xludf.DUMMYFUNCTION("""COMPUTED_VALUE"""),"Oskar R") -> Oskar R | B6: =IFERROR(__xludf.DUMMYFUNCTION("""COMPUTED_VALUE"""),16.0) -> 16 | C6: =IFERROR(__xludf.DUMMYFUNCTION("""COMPUTED_VALUE"""),23.0) -> 23 | D6: =IFERROR(__xludf.DUMMYFUNCTION("""COMPUTED_VALUE"""),48.0) -> 48 | E6: =IFERROR(__xludf.DUMMYFUNCTION("""COMPUTED_VALUE"""),35.0) -> 35 | F6: =IFERROR(__xludf.DUMMYFUNCTION("""COMPUTED_VALUE"""),14.0) -> 14 | G6: =IFERROR(__xludf.DUMMYFUNCTION("""COMPUTED_VALUE"""),0.0) -> 0 | H6: =IFERROR(__xludf.DUMMYFUNCTION("""COMPUTED_VALUE"""),133.0) -> 133 | I6: =IF(H6 <> "", REPT("▮", ROUND((H6 / $H$2) * 30,0)) & REPT("▯", 30 - ROUND((H6 / $H$2) * 30,0)), "") -> ▮▮▮▮▮▮▮▮▮▮▮▮▮▮▮▮▮▮▮▮▮▮▮▯▯▯▯▯▯▯ | J6: =IFERROR(ROUND(H6/F6, 1), "") -> 9.5 | K6: =IFERROR(ROUND(MIN(99, 94 * (0.8*MIN(1, J6/J$2) + 0.2*H6/H$2)),0), "") -> 76 | L6: Benjamin L | M6: =SUMIF(Spelarstatistik!A$2:A179, L6, Spelarstatistik!B$2:B179) -> 1 | N6: =SUMIF(Spelarstatistik!A$2:A179, L6, Spelarstatistik!C$2:C179) -> 4 | O6: =SUMIF(Spelarstatistik!A$2:A179, L6, Spelarstatistik!D$2:D179) -> 16 | P6: =SUMIF(Spelarstatistik!A$2:A179, L6, Spelarstatistik!E$2:E179) -> 14 | Q6: =COUNTIF(Spelarstatistik!A$2:A179, L6) -> 6 | R6: =SUMIF(Matcher!AC$5:AC179, L6, Matcher!AH$5:AH179) -> 0 | S6: =IF(L6 <> "", ROUND(M6 + N6 + 0.5 * O6 + 5 * Q6 + 0.5 * R6,0), "") -> 43
A7: =IFERROR(__xludf.DUMMYFUNCTION("""COMPUTED_VALUE"""),"Ivan N") -> Ivan N | B7: =IFERROR(__xludf.DUMMYFUNCTION("""COMPUTED_VALUE"""),27.0) -> 27 | C7: =IFERROR(__xludf.DUMMYFUNCTION("""COMPUTED_VALUE"""),24.0) -> 24 | D7: =IFERROR(__xludf.DUMMYFUNCTION("""COMPUTED_VALUE"""),35.0) -> 35 | E7: =IFERROR(__xludf.DUMMYFUNCTION("""COMPUTED_VALUE"""),39.0) -> 39 | F7: =IFERROR(__xludf.DUMMYFUNCTION("""COMPUTED_VALUE"""),12.0) -> 12 | G7: =IFERROR(__xludf.DUMMYFUNCTION("""COMPUTED_VALUE"""),0.0) -> 0 | H7: =IFERROR(__xludf.DUMMYFUNCTION("""COMPUTED_VALUE"""),129.0) -> 129 | I7: =IF(H7 <> "", REPT("▮", ROUND((H7 / $H$2) * 30,0)) & REPT("▯", 30 - ROUND((H7 / $H$2) * 30,0)), "") -> ▮▮▮▮▮▮▮▮▮▮▮▮▮▮▮▮▮▮▮▮▮▮▯▯▯▯▯▯▯▯ | J7: =IFERROR(ROUND(H7/F7, 1), "") -> 10.8 | K7: =IFERROR(ROUND(MIN(99, 94 * (0.8*MIN(1, J7/J$2) + 0.2*H7/H$2)),0), "") -> 84 | L7: Branislav D | M7: =SUMIF(Spelarstatistik!A$2:A179, L7, Spelarstatistik!B$2:B179) -> 10 | N7: =SUMIF(Spelarstatistik!A$2:A179, L7, Spelarstatistik!C$2:C179) -> 9 | O7: =SUMIF(Spelarstatistik!A$2:A179, L7, Spelarstatistik!D$2:D179) -> 22 | P7: =SUMIF(Spelarstatistik!A$2:A179, L7, Spelarstatistik!E$2:E179) -> 14 | Q7: =COUNTIF(Spelarstatistik!A$2:A179, L7) -> 5 | R7: =SUMIF(Matcher!AC$5:AC179, L7, Matcher!AH$5:AH179) -> 3 | S7: =IF(L7 <> "", ROUND(M7 + N7 + 0.5 * O7 + 5 * Q7 + 0.5 * R7,0), "") -> 57
A8: =IFERROR(__xludf.DUMMYFUNCTION("""COMPUTED_VALUE"""),"Aria A") -> Aria A | B8: =IFERROR(__xludf.DUMMYFUNCTION("""COMPUTED_VALUE"""),11.0) -> 11 | C8: =IFERROR(__xludf.DUMMYFUNCTION("""COMPUTED_VALUE"""),15.0) -> 15 | D8: =IFERROR(__xludf.DUMMYFUNCTION("""COMPUTED_VALUE"""),33.0) -> 33 | E8: =IFERROR(__xludf.DUMMYFUNCTION("""COMPUTED_VALUE"""),22.0) -> 22 | F8: =IFERROR(__xludf.DUMMYFUNCTION("""COMPUTED_VALUE"""),13.0) -> 13 | G8: =IFERROR(__xludf.DUMMYFUNCTION("""COMPUTED_VALUE"""),0.0) -> 0 | H8: =IFERROR(__xludf.DUMMYFUNCTION("""COMPUTED_VALUE"""),108.0) -> 108 | I8: =IF(H8 <> "", REPT("▮", ROUND((H8 / $H$2) * 30,0)) & REPT("▯", 30 - ROUND((H8 / $H$2) * 30,0)), "") -> ▮▮▮▮▮▮▮▮▮▮▮▮▮▮▮▮▮▮▮▯▯▯▯▯▯▯▯▯▯▯ | J8: =IFERROR(ROUND(H8/F8, 1), "") -> 8.3 | K8: =IFERROR(ROUND(MIN(99, 94 * (0.8*MIN(1, J8/J$2) + 0.2*H8/H$2)),0), "") -> 65 | L8: Casper W | M8: =SUMIF(Spelarstatistik!A$2:A179, L8, Spelarstatistik!B$2:B179) -> 8 | N8: =SUMIF(Spelarstatistik!A$2:A179, L8, Spelarstatistik!C$2:C179) -> 1 | O8: =SUMIF(Spelarstatistik!A$2:A179, L8, Spelarstatistik!D$2:D179) -> 13 | P8: =SUMIF(Spelarstatistik!A$2:A179, L8, Spelarstatistik!E$2:E179) -> 26 | Q8: =COUNTIF(Spelarstatistik!A$2:A179, L8) -> 6 | R8: =SUMIF(Matcher!AC$5:AC179, L8, Matcher!AH$5:AH179) -> 0 | S8: =IF(L8 <> "", ROUND(M8 + N8 + 0.5 * O8 + 5 * Q8 + 0.5 * R8,0), "") -> 46
A9: =IFERROR(__xludf.DUMMYFUNCTION("""COMPUTED_VALUE"""),"Samuel P") -> Samuel P | B9: =IFERROR(__xludf.DUMMYFUNCTION("""COMPUTED_VALUE"""),11.0) -> 11 | C9: =IFERROR(__xludf.DUMMYFUNCTION("""COMPUTED_VALUE"""),29.0) -> 29 | D9: =IFERROR(__xludf.DUMMYFUNCTION("""COMPUTED_VALUE"""),28.0) -> 28 | E9: =IFERROR(__xludf.DUMMYFUNCTION("""COMPUTED_VALUE"""),40.0) -> 40 | F9: =IFERROR(__xludf.DUMMYFUNCTION("""COMPUTED_VALUE"""),10.0) -> 10 | G9: =IFERROR(__xludf.DUMMYFUNCTION("""COMPUTED_VALUE"""),0.0) -> 0 | H9: =IFERROR(__xludf.DUMMYFUNCTION("""COMPUTED_VALUE"""),104.0) -> 104 | I9: =IF(H9 <> "", REPT("▮", ROUND((H9 / $H$2) * 30,0)) & REPT("▯", 30 - ROUND((H9 / $H$2) * 30,0)), "") -> ▮▮▮▮▮▮▮▮▮▮▮▮▮▮▮▮▮▮▯▯▯▯▯▯▯▯▯▯▯▯ | J9: =IFERROR(ROUND(H9/F9, 1), "") -> 10.4 | K9: =IFERROR(ROUND(MIN(99, 94 * (0.8*MIN(1, J9/J$2) + 0.2*H9/H$2)),0), "") -> 79 | L9: Daniel K | M9: =SUMIF(Spelarstatistik!A$2:A179, L9, Spelarstatistik!B$2:B179) -> 24 | N9: =SUMIF(Spelarstatistik!A$2:A179, L9, Spelarstatistik!C$2:C179) -> 20 | O9: =SUMIF(Spelarstatistik!A$2:A179, L9, Spelarstatistik!D$2:D179) -> 37 | P9: =SUMIF(Spelarstatistik!A$2:A179, L9, Spelarstatistik!E$2:E179) -> 36 | Q9: =COUNTIF(Spelarstatistik!A$2:A179, L9) -> 14 | R9: =SUMIF(Matcher!AC$5:AC179, L9, Matcher!AH$5:AH179) -> 0 | S9: =IF(L9 <> "", ROUND(M9 + N9 + 0.5 * O9 + 5 * Q9 + 0.5 * R9,0), "") -> 133
A10: =IFERROR(__xludf.DUMMYFUNCTION("""COMPUTED_VALUE"""),"Dennis F") -> Dennis F | B10: =IFERROR(__xludf.DUMMYFUNCTION("""COMPUTED_VALUE"""),23.0) -> 23 | C10: =IFERROR(__xludf.DUMMYFUNCTION("""COMPUTED_VALUE"""),11.0) -> 11 | D10: =IFERROR(__xludf.DUMMYFUNCTION("""COMPUTED_VALUE"""),30.0) -> 30 | E10: =IFERROR(__xludf.DUMMYFUNCTION("""COMPUTED_VALUE"""),20.0) -> 20 | F10: =IFERROR(__xludf.DUMMYFUNCTION("""COMPUTED_VALUE"""),9.0) -> 9 | G10: =IFERROR(__xludf.DUMMYFUNCTION("""COMPUTED_VALUE"""),6.0) -> 6 | H10: =IFERROR(__xludf.DUMMYFUNCTION("""COMPUTED_VALUE"""),97.0) -> 97 | I10: =IF(H10 <> "", REPT("▮", ROUND((H10 / $H$2) * 30,0)) & REPT("▯", 30 - ROUND((H10 / $H$2) * 30,0)), "") -> ▮▮▮▮▮▮▮▮▮▮▮▮▮▮▮▮▮▯▯▯▯▯▯▯▯▯▯▯▯▯ | J10: =IFERROR(ROUND(H10/F10, 1), "") -> 10.8 | K10: =IFERROR(ROUND(MIN(99, 94 * (0.8*MIN(1, J10/J$2) + 0.2*H10/H$2)),0), "") -> 80 | L10: Daniel Ö | M10: =SUMIF(Spelarstatistik!A$2:A179, L10, Spelarstatistik!B$2:B179) -> 26 | N10: =SUMIF(Spelarstatistik!A$2:A179, L10, Spelarstatistik!C$2:C179) -> 12 | O10: =SUMIF(Spelarstatistik!A$2:A179, L10, Spelarstatistik!D$2:D179) -> 19 | P10: =SUMIF(Spelarstatistik!A$2:A179, L10, Spelarstatistik!E$2:E179) -> 15 | Q10: =COUNTIF(Spelarstatistik!A$2:A179, L10) -> 6 | R10: =SUMIF(Matcher!AC$5:AC179, L10, Matcher!AH$5:AH179) -> 0 | S10: =IF(L10 <> "", ROUND(M10 + N10 + 0.5 * O10 + 5 * Q10 + 0.5 * R10,0), "") -> 78
A11: =IFERROR(__xludf.DUMMYFUNCTION("""COMPUTED_VALUE"""),"Yvan I") -> Yvan I | B11: =IFERROR(__xludf.DUMMYFUNCTION("""COMPUTED_VALUE"""),16.0) -> 16 | C11: =IFERROR(__xludf.DUMMYFUNCTION("""COMPUTED_VALUE"""),9.0) -> 9 | D11: =IFERROR(__xludf.DUMMYFUNCTION("""COMPUTED_VALUE"""),13.0) -> 13 | E11: =IFERROR(__xludf.DUMMYFUNCTION("""COMPUTED_VALUE"""),47.0) -> 47 | F11: =IFERROR(__xludf.DUMMYFUNCTION("""COMPUTED_VALUE"""),12.0) -> 12 | G11: =IFERROR(__xludf.DUMMYFUNCTION("""COMPUTED_VALUE"""),0.0) -> 0 | H11: =IFERROR(__xludf.DUMMYFUNCTION("""COMPUTED_VALUE"""),92.0) -> 92 | I11: =IF(H11 <> "", REPT("▮", ROUND((H11 / $H$2) * 30,0)) & REPT("▯", 30 - ROUND((H11 / $H$2) * 30,0)), "") -> ▮▮▮▮▮▮▮▮▮▮▮▮▮▮▮▮▯▯▯▯▯▯▯▯▯▯▯▯▯▯ | J11: =IFERROR(ROUND(H11/F11, 1), "") -> 7.7 | K11: =IFERROR(ROUND(MIN(99, 94 * (0.8*MIN(1, J11/J$2) + 0.2*H11/H$2)),0), "") -> 60 | L11: Dennis F | M11: =SUMIF(Spelarstatistik!A$2:A179, L11, Spelarstatistik!B$2:B179) -> 23 | N11: =SUMIF(Spelarstatistik!A$2:A179, L11, Spelarstatistik!C$2:C179) -> 11 | O11: =SUMIF(Spelarstatistik!A$2:A179, L11, Spelarstatistik!D$2:D179) -> 30 | P11: =SUMIF(Spelarstatistik!A$2:A179, L11, Spelarstatistik!E$2:E179) -> 20 | Q11: =COUNTIF(Spelarstatistik!A$2:A179, L11) -> 9 | R11: =SUMIF(Matcher!AC$5:AC179, L11, Matcher!AH$5:AH179) -> 6 | S11: =IF(L11 <> "", ROUND(M11 + N11 + 0.5 * O11 + 5 * Q11 + 0.5 * R11,0), "") -> 97
A12: =IFERROR(__xludf.DUMMYFUNCTION("""COMPUTED_VALUE"""),"Shahir I") -> Shahir I | B12: =IFERROR(__xludf.DUMMYFUNCTION("""COMPUTED_VALUE"""),10.0) -> 10 | C12: =IFERROR(__xludf.DUMMYFUNCTION("""COMPUTED_VALUE"""),11.0) -> 11 | D12: =IFERROR(__xludf.DUMMYFUNCTION("""COMPUTED_VALUE"""),34.0) -> 34 | E12: =IFERROR(__xludf.DUMMYFUNCTION("""COMPUTED_VALUE"""),23.0) -> 23 | F12: =IFERROR(__xludf.DUMMYFUNCTION("""COMPUTED_VALUE"""),10.0) -> 10 | G12: =IFERROR(__xludf.DUMMYFUNCTION("""COMPUTED_VALUE"""),0.0) -> 0 | H12: =IFERROR(__xludf.DUMMYFUNCTION("""COMPUTED_VALUE"""),88.0) -> 88 | I12: =IF(H12 <> "", REPT("▮", ROUND((H12 / $H$2) * 30,0)) & REPT("▯", 30 - ROUND((H12 / $H$2) * 30,0)), "") -> ▮▮▮▮▮▮▮▮▮▮▮▮▮▮▮▯▯▯▯▯▯▯▯▯▯▯▯▯▯▯ | J12: =IFERROR(ROUND(H12/F12, 1), "") -> 8.8 | K12: =IFERROR(ROUND(MIN(99, 94 * (0.8*MIN(1, J12/J$2) + 0.2*H12/H$2)),0), "") -> 67 | L12: Einar D | M12: =SUMIF(Spelarstatistik!A$2:A179, L12, Spelarstatistik!B$2:B179) -> 0 | N12: =SUMIF(Spelarstatistik!A$2:A179, L12, Spelarstatistik!C$2:C179) -> 0 | O12: =SUMIF(Spelarstatistik!A$2:A179, L12, Spelarstatistik!D$2:D179) -> 6 | P12: =SUMIF(Spelarstatistik!A$2:A179, L12, Spelarstatistik!E$2:E179) -> 9 | Q12: =COUNTIF(Spelarstatistik!A$2:A179, L12) -> 2 | R12: =SUMIF(Matcher!AC$5:AC179, L12, Matcher!AH$5:AH179) -> 9 | S12: =IF(L12 <> "", ROUND(M12 + N12 + 0.5 * O12 + 5 * Q12 + 0.5 * R12,0), "") -> 18
A13: =IFERROR(__xludf.DUMMYFUNCTION("""COMPUTED_VALUE"""),"Daniel Ö") -> Daniel Ö | B13: =IFERROR(__xludf.DUMMYFUNCTION("""COMPUTED_VALUE"""),26.0) -> 26 | C13: =IFERROR(__xludf.DUMMYFUNCTION("""COMPUTED_VALUE"""),12.0) -> 12 | D13: =IFERROR(__xludf.DUMMYFUNCTION("""COMPUTED_VALUE"""),19.0) -> 19 | E13: =IFERROR(__xludf.DUMMYFUNCTION("""COMPUTED_VALUE"""),15.0) -> 15 | F13: =IFERROR(__xludf.DUMMYFUNCTION("""COMPUTED_VALUE"""),6.0) -> 6 | G13: =IFERROR(__xludf.DUMMYFUNCTION("""COMPUTED_VALUE"""),0.0) -> 0 | H13: =IFERROR(__xludf.DUMMYFUNCTION("""COMPUTED_VALUE"""),78.0) -> 78 | I13: =IF(H13 <> "", REPT("▮", ROUND((H13 / $H$2) * 30,0)) & REPT("▯", 30 - ROUND((H13 / $H$2) * 30,0)), "") -> ▮▮▮▮▮▮▮▮▮▮▮▮▮▯▯▯▯▯▯▯▯▯▯▯▯▯▯▯▯▯ | J13: =IFERROR(ROUND(H13/F13, 1), "") -> 13 | K13: =IFERROR(ROUND(MIN(99, 94 * (0.8*MIN(1, J13/J$2) + 0.2*H13/H$2)),0), "") -> 84 | L13: Emil A | M13: =SUMIF(Spelarstatistik!A$2:A179, L13, Spelarstatistik!B$2:B179) -> 3 | N13: =SUMIF(Spelarstatistik!A$2:A179, L13, Spelarstatistik!C$2:C179) -> 6 | O13: =SUMIF(Spelarstatistik!A$2:A179, L13, Spelarstatistik!D$2:D179) -> 14 | P13: =SUMIF(Spelarstatistik!A$2:A179, L13, Spelarstatistik!E$2:E179) -> 17 | Q13: =COUNTIF(Spelarstatistik!A$2:A179, L13) -> 5 | R13: =SUMIF(Matcher!AC$5:AC179, L13, Matcher!AH$5:AH179) -> 0 | S13: =IF(L13 <> "", ROUND(M13 + N13 + 0.5 * O13 + 5 * Q13 + 0.5 * R13,0), "") -> 41
A14: =IFERROR(__xludf.DUMMYFUNCTION("""COMPUTED_VALUE"""),"Pontus S") -> Pontus S | B14: =IFERROR(__xludf.DUMMYFUNCTION("""COMPUTED_VALUE"""),0.0) -> 0 | C14: =IFERROR(__xludf.DUMMYFUNCTION("""COMPUTED_VALUE"""),21.0) -> 21 | D14: =IFERROR(__xludf.DUMMYFUNCTION("""COMPUTED_VALUE"""),4.0) -> 4 | E14: =IFERROR(__xludf.DUMMYFUNCTION("""COMPUTED_VALUE"""),1.0) -> 1 | F14: =IFERROR(__xludf.DUMMYFUNCTION("""COMPUTED_VALUE"""),9.0) -> 9 | G14: =IFERROR(__xludf.DUMMYFUNCTION("""COMPUTED_VALUE"""),6.0) -> 6 | H14: =IFERROR(__xludf.DUMMYFUNCTION("""COMPUTED_VALUE"""),71.0) -> 71 | I14: =IF(H14 <> "", REPT("▮", ROUND((H14 / $H$2) * 30,0)) & REPT("▯", 30 - ROUND((H14 / $H$2) * 30,0)), "") -> ▮▮▮▮▮▮▮▮▮▮▮▮▯▯▯▯▯▯▯▯▯▯▯▯▯▯▯▯▯▯ | J14: =IFERROR(ROUND(H14/F14, 1), "") -> 7.9 | K14: =IFERROR(ROUND(MIN(99, 94 * (0.8*MIN(1, J14/J$2) + 0.2*H14/H$2)),0), "") -> 59 | L14: Emil B | M14: =SUMIF(Spelarstatistik!A$2:A179, L14, Spelarstatistik!B$2:B179) -> 3 | N14: =SUMIF(Spelarstatistik!A$2:A179, L14, Spelarstatistik!C$2:C179) -> 9 | O14: =SUMIF(Spelarstatistik!A$2:A179, L14, Spelarstatistik!D$2:D179) -> 56 | P14: =SUMIF(Spelarstatistik!A$2:A179, L14, Spelarstatistik!E$2:E179) -> 57 | Q14: =COUNTIF(Spelarstatistik!A$2:A179, L14) -> 14 | R14: =SUMIF(Matcher!AC$5:AC179, L14, Matcher!AH$5:AH179) -> 72 | S14: =IF(L14 <> "", ROUND(M14 + N14 + 0.5 * O14 + 5 * Q14 + 0.5 * R14,0), "") -> 146
A15: =IFERROR(__xludf.DUMMYFUNCTION("""COMPUTED_VALUE"""),"Isak L") -> Isak L | B15: =IFERROR(__xludf.DUMMYFUNCTION("""COMPUTED_VALUE"""),13.0) -> 13 | C15: =IFERROR(__xludf.DUMMYFUNCTION("""COMPUTED_VALUE"""),11.0) -> 11 | D15: =IFERROR(__xludf.DUMMYFUNCTION("""COMPUTED_VALUE"""),17.0) -> 17 | E15: =IFERROR(__xludf.DUMMYFUNCTION("""COMPUTED_VALUE"""),27.0) -> 27 | F15: =IFERROR(__xludf.DUMMYFUNCTION("""COMPUTED_VALUE"""),7.0) -> 7 | G15: =IFERROR(__xludf.DUMMYFUNCTION("""COMPUTED_VALUE"""),0.0) -> 0 | H15: =IFERROR(__xludf.DUMMYFUNCTION("""COMPUTED_VALUE"""),68.0) -> 68 | I15: =IF(H15 <> "", REPT("▮", ROUND((H15 / $H$2) * 30,0)) & REPT("▯", 30 - ROUND((H15 / $H$2) * 30,0)), "") -> ▮▮▮▮▮▮▮▮▮▮▮▮▯▯▯▯▯▯▯▯▯▯▯▯▯▯▯▯▯▯ | J15: =IFERROR(ROUND(H15/F15, 1), "") -> 9.7 | K15: =IFERROR(ROUND(MIN(99, 94 * (0.8*MIN(1, J15/J$2) + 0.2*H15/H$2)),0), "") -> 70 | L15: Emil F | M15: =SUMIF(Spelarstatistik!A$2:A179, L15, Spelarstatistik!B$2:B179) -> 9 | N15: =SUMIF(Spelarstatistik!A$2:A179, L15, Spelarstatistik!C$2:C179) -> 3 | O15: =SUMIF(Spelarstatistik!A$2:A179, L15, Spelarstatistik!D$2:D179) -> 8 | P15: =SUMIF(Spelarstatistik!A$2:A179, L15, Spelarstatistik!E$2:E179) -> 6 | Q15: =COUNTIF(Spelarstatistik!A$2:A179, L15) -> 2 | R15: =SUMIF(Matcher!AC$5:AC179, L15, Matcher!AH$5:AH179) -> 0 | S15: =IF(L15 <> "", ROUND(M15 + N15 + 0.5 * O15 + 5 * Q15 + 0.5 * R15,0), "") -> 26
A16: =IFERROR(__xludf.DUMMYFUNCTION("""COMPUTED_VALUE"""),"Jesper N") -> Jesper N | B16: =IFERROR(__xludf.DUMMYFUNCTION("""COMPUTED_VALUE"""),0.0) -> 0 | C16: =IFERROR(__xludf.DUMMYFUNCTION("""COMPUTED_VALUE"""),7.0) -> 7 | D16: =IFERROR(__xludf.DUMMYFUNCTION("""COMPUTED_VALUE"""),21.0) -> 21 | E16: =IFERROR(__xludf.DUMMYFUNCTION("""COMPUTED_VALUE"""),15.0) -> 15 | F16: =IFERROR(__xludf.DUMMYFUNCTION("""COMPUTED_VALUE"""),7.0) -> 7 | G16: =IFERROR(__xludf.DUMMYFUNCTION("""COMPUTED_VALUE"""),20.0) -> 20 | H16: =IFERROR(__xludf.DUMMYFUNCTION("""COMPUTED_VALUE"""),63.0) -> 63 | I16: =IF(H16 <> "", REPT("▮", ROUND((H16 / $H$2) * 30,0)) & REPT("▯", 30 - ROUND((H16 / $H$2) * 30,0)), "") -> ▮▮▮▮▮▮▮▮▮▮▮▯▯▯▯▯▯▯▯▯▯▯▯▯▯▯▯▯▯▯ | J16: =IFERROR(ROUND(H16/F16, 1), "") -> 9 | K16: =IFERROR(ROUND(MIN(99, 94 * (0.8*MIN(1, J16/J$2) + 0.2*H16/H$2)),0), "") -> 65 | L16: Eskil K | M16: =SUMIF(Spelarstatistik!A$2:A179, L16, Spelarstatistik!B$2:B179) -> 11 | N16: =SUMIF(Spelarstatistik!A$2:A179, L16, Spelarstatistik!C$2:C179) -> 2 | O16: =SUMIF(Spelarstatistik!A$2:A179, L16, Spelarstatistik!D$2:D179) -> 16 | P16: =SUMIF(Spelarstatistik!A$2:A179, L16, Spelarstatistik!E$2:E179) -> 11 | Q16: =COUNTIF(Spelarstatistik!A$2:A179, L16) -> 5 | R16: =SUMIF(Matcher!AC$5:AC179, L16, Matcher!AH$5:AH179) -> 0 | S16: =IF(L16 <> "", ROUND(M16 + N16 + 0.5 * O16 + 5 * Q16 + 0.5 * R16,0), "") -> 46
A17: =IFERROR(__xludf.DUMMYFUNCTION("""COMPUTED_VALUE"""),"Sebastian E") -> Sebastian E | B17: =IFERROR(__xludf.DUMMYFUNCTION("""COMPUTED_VALUE"""),10.0) -> 10 | C17: =IFERROR(__xludf.DUMMYFUNCTION("""COMPUTED_VALUE"""),8.0) -> 8 | D17: =IFERROR(__xludf.DUMMYFUNCTION("""COMPUTED_VALUE"""),18.0) -> 18 | E17: =IFERROR(__xludf.DUMMYFUNCTION("""COMPUTED_VALUE"""),21.0) -> 21 | F17: =IFERROR(__xludf.DUMMYFUNCTION("""COMPUTED_VALUE"""),7.0) -> 7 | G17: =IFERROR(__xludf.DUMMYFUNCTION("""COMPUTED_VALUE"""),0.0) -> 0 | H17: =IFERROR(__xludf.DUMMYFUNCTION("""COMPUTED_VALUE"""),62.0) -> 62 | I17: =IF(H17 <> "", REPT("▮", ROUND((H17 / $H$2) * 30,0)) & REPT("▯", 30 - ROUND((H17 / $H$2) * 30,0)), "") -> ▮▮▮▮▮▮▮▮▮▮▮▯▯▯▯▯▯▯▯▯▯▯▯▯▯▯▯▯▯▯ | J17: =IFERROR(ROUND(H17/F17, 1), "") -> 8.9 | K17: =IFERROR(ROUND(MIN(99, 94 * (0.8*MIN(1, J17/J$2) + 0.2*H17/H$2)),0), "") -> 64 | L17: Fredrik C | M17: =SUMIF(Spelarstatistik!A$2:A179, L17, Spelarstatistik!B$2:B179) -> 3 | N17: =SUMIF(Spelarstatistik!A$2:A179, L17, Spelarstatistik!C$2:C179) -> 4 | O17: =SUMIF(Spelarstatistik!A$2:A179, L17, Spelarstatistik!D$2:D179) -> 6 | P17: =SUMIF(Spelarstatistik!A$2:A179, L17, Spelarstatistik!E$2:E179) -> 0 | Q17: =COUNTIF(Spelarstatistik!A$2:A179, L17) -> 1 | R17: =SUMIF(Matcher!AC$5:AC179, L17, Matcher!AH$5:AH179) -> 0 | S17: =IF(L17 <> "", ROUND(M17 + N17 + 0.5 * O17 + 5 * Q17 + 0.5 * R17,0), "") -> 15
A18: =IFERROR(__xludf.DUMMYFUNCTION("""COMPUTED_VALUE"""),"Branislav D") -> Branislav D | B18: =IFERROR(__xludf.DUMMYFUNCTION("""COMPUTED_VALUE"""),10.0) -> 10 | C18: =IFERROR(__xludf.DUMMYFUNCTION("""COMPUTED_VALUE"""),9.0) -> 9 | D18: =IFERROR(__xludf.DUMMYFUNCTION("""COMPUTED_VALUE"""),22.0) -> 22 | E18: =IFERROR(__xludf.DUMMYFUNCTION("""COMPUTED_VALUE"""),14.0) -> 14 | F18: =IFERROR(__xludf.DUMMYFUNCTION("""COMPUTED_VALUE"""),5.0) -> 5 | G18: =IFERROR(__xludf.DUMMYFUNCTION("""COMPUTED_VALUE"""),3.0) -> 3 | H18: =IFERROR(__xludf.DUMMYFUNCTION("""COMPUTED_VALUE"""),57.0) -> 57 | I18: =IF(H18 <> "", REPT("▮", ROUND((H18 / $H$2) * 30,0)) & REPT("▯", 30 - ROUND((H18 / $H$2) * 30,0)), "") -> ▮▮▮▮▮▮▮▮▮▮▯▯▯▯▯▯▯▯▯▯▯▯▯▯▯▯▯▯▯▯ | J18: =IFERROR(ROUND(H18/F18, 1), "") -> 11.4 | K18: =IFERROR(ROUND(MIN(99, 94 * (0.8*MIN(1, J18/J$2) + 0.2*H18/H$2)),0), "") -> 80 | L18: George | M18: =SUMIF(Spelarstatistik!A$2:A179, L18, Spelarstatistik!B$2:B179) -> 1 | N18: =SUMIF(Spelarstatistik!A$2:A179, L18, Spelarstatistik!C$2:C179) -> 1 | O18: =SUMIF(Spelarstatistik!A$2:A179, L18, Spelarstatistik!D$2:D179) -> 9 | P18: =SUMIF(Spelarstatistik!A$2:A179, L18, Spelarstatistik!E$2:E179) -> 6 | Q18: =COUNTIF(Spelarstatistik!A$2:A179, L18) -> 2 | R18: =SUMIF(Matcher!AC$5:AC179, L18, Matcher!AH$5:AH179) -> 0 | S18: =IF(L18 <> "", ROUND(M18 + N18 + 0.5 * O18 + 5 * Q18 + 0.5 * R18,0), "") -> 17
A19: =IFERROR(__xludf.DUMMYFUNCTION("""COMPUTED_VALUE"""),"Henrik O") -> Henrik O | B19: =IFERROR(__xludf.DUMMYFUNCTION("""COMPUTED_VALUE"""),9.0) -> 9 | C19: =IFERROR(__xludf.DUMMYFUNCTION("""COMPUTED_VALUE"""),4.0) -> 4 | D19: =IFERROR(__xludf.DUMMYFUNCTION("""COMPUTED_VALUE"""),19.0) -> 19 | E19: =IFERROR(__xludf.DUMMYFUNCTION("""COMPUTED_VALUE"""),14.0) -> 14 | F19: =IFERROR(__xludf.DUMMYFUNCTION("""COMPUTED_VALUE"""),5.0) -> 5 | G19: =IFERROR(__xludf.DUMMYFUNCTION("""COMPUTED_VALUE"""),0.0) -> 0 | H19: =IFERROR(__xludf.DUMMYFUNCTION("""COMPUTED_VALUE"""),48.0) -> 48 | I19: =IF(H19 <> "", REPT("▮", ROUND((H19 / $H$2) * 30,0)) & REPT("▯", 30 - ROUND((H19 / $H$2) * 30,0)), "") -> ▮▮▮▮▮▮▮▮▯▯▯▯▯▯▯▯▯▯▯▯▯▯▯▯▯▯▯▯▯▯ | J19: =IFERROR(ROUND(H19/F19, 1), "") -> 9.6 | K19: =IFERROR(ROUND(MIN(99, 94 * (0.8*MIN(1, J19/J$2) + 0.2*H19/H$2)),0), "") -> 67 | L19: George T | M19: =SUMIF(Spelarstatistik!A$2:A179, L19, Spelarstatistik!B$2:B179) -> 4 | N19: =SUMIF(Spelarstatistik!A$2:A179, L19, Spelarstatistik!C$2:C179) -> 7 | O19: =SUMIF(Spelarstatistik!A$2:A179, L19, Spelarstatistik!D$2:D179) -> 12 | P19: =SUMIF(Spelarstatistik!A$2:A179, L19, Spelarstatistik!E$2:E179) -> 14 | Q19: =COUNTIF(Spelarstatistik!A$2:A179, L19) -> 4 | R19: =SUMIF(Matcher!AC$5:AC179, L19, Matcher!AH$5:AH179) -> 0 | S19: =IF(L19 <> "", ROUND(M19 + N19 + 0.5 * O19 + 5 * Q19 + 0.5 * R19,0), "") -> 37
A20: =IFERROR(__xludf.DUMMYFUNCTION("""COMPUTED_VALUE"""),"Casper W") -> Casper W | B20: =IFERROR(__xludf.DUMMYFUNCTION("""COMPUTED_VALUE"""),8.0) -> 8 | C20: =IFERROR(__xludf.DUMMYFUNCTION("""COMPUTED_VALUE"""),1.0) -> 1 | D20: =IFERROR(__xludf.DUMMYFUNCTION("""COMPUTED_VALUE"""),13.0) -> 13 | E20: =IFERROR(__xludf.DUMMYFUNCTION("""COMPUTED_VALUE"""),26.0) -> 26 | F20: =IFERROR(__xludf.DUMMYFUNCTION("""COMPUTED_VALUE"""),6.0) -> 6 | G20: =IFERROR(__xludf.DUMMYFUNCTION("""COMPUTED_VALUE"""),0.0) -> 0 | H20: =IFERROR(__xludf.DUMMYFUNCTION("""COMPUTED_VALUE"""),46.0) -> 46 | I20: =IF(H20 <> "", REPT("▮", ROUND((H20 / $H$2) * 30,0)) & REPT("▯", 30 - ROUND((H20 / $H$2) * 30,0)), "") -> ▮▮▮▮▮▮▮▮▯▯▯▯▯▯▯▯▯▯▯▯▯▯▯▯▯▯▯▯▯▯ | J20: =IFERROR(ROUND(H20/F20, 1), "") -> 7.7 | K20: =IFERROR(ROUND(MIN(99, 94 * (0.8*MIN(1, J20/J$2) + 0.2*H20/H$2)),0), "") -> 55 | L20: Georgios T | M20: =SUMIF(Spelarstatistik!A$2:A179, L20, Spelarstatistik!B$2:B179) -> 1 | N20: =SUMIF(Spelarstatistik!A$2:A179, L20, Spelarstatistik!C$2:C179) -> 1 | O20: =SUMIF(Spelarstatistik!A$2:A179, L20, Spelarstatistik!D$2:D179) -> 5 | P20: =SUMIF(Spelarstatistik!A$2:A179, L20, Spelarstatistik!E$2:E179) -> 1 | Q20: =COUNTIF(Spelarstatistik!A$2:A179, L20) -> 1 | R20: =SUMIF(Matcher!AC$5:AC179, L20, Matcher!AH$5:AH179) -> 0 | S20: =IF(L20 <> "", ROUND(M20 + N20 + 0.5 * O20 + 5 * Q20 + 0.5 * R20,0), "") -> 10
A21: =IFERROR(__xludf.DUMMYFUNCTION("""COMPUTED_VALUE"""),"Eskil K") -> Eskil K | B21: =IFERROR(__xludf.DUMMYFUNCTION("""COMPUTED_VALUE"""),11.0) -> 11 | C21: =IFERROR(__xludf.DUMMYFUNCTION("""COMPUTED_VALUE"""),2.0) -> 2 | D21: =IFERROR(__xludf.DUMMYFUNCTION("""COMPUTED_VALUE"""),16.0) -> 16 | E21: =IFERROR(__xludf.DUMMYFUNCTION("""COMPUTED_VALUE"""),11.0) -> 11 | F21: =IFERROR(__xludf.DUMMYFUNCTION("""COMPUTED_VALUE"""),5.0) -> 5 | G21: =IFERROR(__xludf.DUMMYFUNCTION("""COMPUTED_VALUE"""),0.0) -> 0 | H21: =IFERROR(__xludf.DUMMYFUNCTION("""COMPUTED_VALUE"""),46.0) -> 46 | I21: =IF(H21 <> "", REPT("▮", ROUND((H21 / $H$2) * 30,0)) & REPT("▯", 30 - ROUND((H21 / $H$2) * 30,0)), "") -> ▮▮▮▮▮▮▮▮▯▯▯▯▯▯▯▯▯▯▯▯▯▯▯▯▯▯▯▯▯▯ | J21: =IFERROR(ROUND(H21/F21, 1), "") -> 9.2 | K21: =IFERROR(ROUND(MIN(99, 94 * (0.8*MIN(1, J21/J$2) + 0.2*H21/H$2)),0), "") -> 65 | L21: Gustav X | M21: =SUMIF(Spelarstatistik!A$2:A179, L21, Spelarstatistik!B$2:B179) -> 5 | N21: =SUMIF(Spelarstatistik!A$2:A179, L21, Spelarstatistik!C$2:C179) -> 0 | O21: =SUMIF(Spelarstatistik!A$2:A179, L21, Spelarstatistik!D$2:D179) -> 4 | P21: =SUMIF(Spelarstatistik!A$2:A179, L21, Spelarstatistik!E$2:E179) -> 2 | Q21: =COUNTIF(Spelarstatistik!A$2:A179, L21) -> 1 | R21: =SUMIF(Matcher!AC$5:AC179, L21, Matcher!AH$5:AH179) -> 0 | S21: =IF(L21 <> "", ROUND(M21 + N21 + 0.5 * O21 + 5 * Q21 + 0.5 * R21,0), "") -> 12
A22: =IFERROR(__xludf.DUMMYFUNCTION("""COMPUTED_VALUE"""),"Milos G") -> Milos G | B22: =IFERROR(__xludf.DUMMYFUNCTION("""COMPUTED_VALUE"""),14.0) -> 14 | C22: =IFERROR(__xludf.DUMMYFUNCTION("""COMPUTED_VALUE"""),9.0) -> 9 | D22: =IFERROR(__xludf.DUMMYFUNCTION("""COMPUTED_VALUE"""),13.0) -> 13 | E22: =IFERROR(__xludf.DUMMYFUNCTION("""COMPUTED_VALUE"""),6.0) -> 6 | F22: =IFERROR(__xludf.DUMMYFUNCTION("""COMPUTED_VALUE"""),3.0) -> 3 | G22: =IFERROR(__xludf.DUMMYFUNCTION("""COMPUTED_VALUE"""),0.0) -> 0 | H22: =IFERROR(__xludf.DUMMYFUNCTION("""COMPUTED_VALUE"""),45.0) -> 45 | I22: =IF(H22 <> "", REPT("▮", ROUND((H22 / $H$2) * 30,0)) & REPT("▯", 30 - ROUND((H22 / $H$2) * 30,0)), "") -> ▮▮▮▮▮▮▮▮▯▯▯▯▯▯▯▯▯▯▯▯▯▯▯▯▯▯▯▯▯▯ | J22: =IFERROR(ROUND(H22/F22, 1), "") -> 15 | K22: =IFERROR(ROUND(MIN(99, 94 * (0.8*MIN(1, J22/J$2) + 0.2*H22/H$2)),0), "") -> 80 | L22: Hampus W | M22: =SUMIF(Spelarstatistik!A$2:A179, L22, Spelarstatistik!B$2:B179) -> 0 | N22: =SUMIF(Spelarstatistik!A$2:A179, L22, Spelarstatistik!C$2:C179) -> 0 | O22: =SUMIF(Spelarstatistik!A$2:A179, L22, Spelarstatistik!D$2:D179) -> 3 | P22: =SUMIF(Spelarstatistik!A$2:A179, L22, Spelarstatistik!E$2:E179) -> 1 | Q22: =COUNTIF(Spelarstatistik!A$2:A179, L22) -> 1 | R22: =SUMIF(Matcher!AC$5:AC179, L22, Matcher!AH$5:AH179) -> 0 | S22: =IF(L22 <> "", ROUND(M22 + N22 + 0.5 * O22 + 5 * Q22 + 0.5 * R22,0), "") -> 7
A23: =IFERROR(__xludf.DUMMYFUNCTION("""COMPUTED_VALUE"""),"Benjamin L") -> Benjamin L | B23: =IFERROR(__xludf.DUMMYFUNCTION("""COMPUTED_VALUE"""),1.0) -> 1 | C23: =IFERROR(__xludf.DUMMYFUNCTION("""COMPUTED_VALUE"""),4.0) -> 4 | D23: =IFERROR(__xludf.DUMMYFUNCTION("""COMPUTED_VALUE"""),16.0) -> 16 | E23: =IFERROR(__xludf.DUMMYFUNCTION("""COMPUTED_VALUE"""),14.0) -> 14 | F23: =IFERROR(__xludf.DUMMYFUNCTION("""COMPUTED_VALUE"""),6.0) -> 6 | G23: =IFERROR(__xludf.DUMMYFUNCTION("""COMPUTED_VALUE"""),0.0) -> 0 | H23: =IFERROR(__xludf.DUMMYFUNCTION("""COMPUTED_VALUE"""),43.0) -> 43 | I23: =IF(H23 <> "", REPT("▮", ROUND((H23 / $H$2) * 30,0)) & REPT("▯", 30 - ROUND((H23 / $H$2) * 30,0)), "") -> ▮▮▮▮▮▮▮▯▯▯▯▯▯▯▯▯▯▯▯▯▯▯▯▯▯▯▯▯▯▯ | J23: =IFERROR(ROUND(H23/F23, 1), "") -> 7.2 | K23: =IFERROR(ROUND(MIN(99, 94 * (0.8*MIN(1, J23/J$2) + 0.2*H23/H$2)),0), "") -> 51 | L23: Henrik O | M23: =SUMIF(Spelarstatistik!A$2:A179, L23, Spelarstatistik!B$2:B179) -> 9 | N23: =SUMIF(Spelarstatistik!A$2:A179, L23, Spelarstatistik!C$2:C179) -> 4 | O23: =SUMIF(Spelarstatistik!A$2:A179, L23, Spelarstatistik!D$2:D179) -> 19 | P23: =SUMIF(Spelarstatistik!A$2:A179, L23, Spelarstatistik!E$2:E179) -> 14 | Q23: =COUNTIF(Spelarstatistik!A$2:A179, L23) -> 5 | R23: =SUMIF(Matcher!AC$5:AC179, L23, Matcher!AH$5:AH179) -> 0 | S23: =IF(L23 <> "", ROUND(M23 + N23 + 0.5 * O23 + 5 * Q23 + 0.5 * R23,0), "") -> 48
A24: =IFERROR(__xludf.DUMMYFUNCTION("""COMPUTED_VALUE"""),"Albert A") -> Albert A | B24: =IFERROR(__xludf.DUMMYFUNCTION("""COMPUTED_VALUE"""),3.0) -> 3 | C24: =IFERROR(__xludf.DUMMYFUNCTION("""COMPUTED_VALUE"""),2.0) -> 2 | D24: =IFERROR(__xludf.DUMMYFUNCTION("""COMPUTED_VALUE"""),13.0) -> 13 | E24: =IFERROR(__xludf.DUMMYFUNCTION("""COMPUTED_VALUE"""),19.0) -> 19 | F24: =IFERROR(__xludf.DUMMYFUNCTION("""COMPUTED_VALUE"""),6.0) -> 6 | G24: =IFERROR(__xludf.DUMMYFUNCTION("""COMPUTED_VALUE"""),0.0) -> 0 | H24: =IFERROR(__xludf.DUMMYFUNCTION("""COMPUTED_VALUE"""),42.0) -> 42 | I24: =IF(H24 <> "", REPT("▮", ROUND((H24 / $H$2) * 30,0)) & REPT("▯", 30 - ROUND((H24 / $H$2) * 30,0)), "") -> ▮▮▮▮▮▮▮▯▯▯▯▯▯▯▯▯▯▯▯▯▯▯▯▯▯▯▯▯▯▯ | J24: =IFERROR(ROUND(H24/F24, 1), "") -> 7 | K24: =IFERROR(ROUND(MIN(99, 94 * (0.8*MIN(1, J24/J$2) + 0.2*H24/H$2)),0), "") -> 50 | L24: Immanuel A | M24: =SUMIF(Spelarstatistik!A$2:A179, L24, Spelarstatistik!B$2:B179) -> 1 | N24: =SUMIF(Spelarstatistik!A$2:A179, L24, Spelarstatistik!C$2:C179) -> 1 | O24: =SUMIF(Spelarstatistik!A$2:A179, L24, Spelarstatistik!D$2:D179) -> 0 | P24: =SUMIF(Spelarstatistik!A$2:A179, L24, Spelarstatistik!E$2:E179) -> 7 | Q24: =COUNTIF(Spelarstatistik!A$2:A179, L24) -> 1 | R24: =SUMIF(Matcher!AC$5:AC179, L24, Matcher!AH$5:AH179) -> 0 | S24: =IF(L24 <> "", ROUND(M24 + N24 + 0.5 * O24 + 5 * Q24 + 0.5 * R24,0), "") -> 7
A25: =IFERROR(__xludf.DUMMYFUNCTION("""COMPUTED_VALUE"""),"Pontus B") -> Pontus B | B25: =IFERROR(__xludf.DUMMYFUNCTION("""COMPUTED_VALUE"""),9.0) -> 9 | C25: =IFERROR(__xludf.DUMMYFUNCTION("""COMPUTED_VALUE"""),8.0) -> 8 | D25: =IFERROR(__xludf.DUMMYFUNCTION("""COMPUTED_VALUE"""),9.0) -> 9 | E25: =IFERROR(__xludf.DUMMYFUNCTION("""COMPUTED_VALUE"""),12.0) -> 12 | F25: =IFERROR(__xludf.DUMMYFUNCTION("""COMPUTED_VALUE"""),4.0) -> 4 | G25: =IFERROR(__xludf.DUMMYFUNCTION("""COMPUTED_VALUE"""),0.0) -> 0 | H25: =IFERROR(__xludf.DUMMYFUNCTION("""COMPUTED_VALUE"""),42.0) -> 42 | I25: =IF(H25 <> "", REPT("▮", ROUND((H25 / $H$2) * 30,0)) & REPT("▯", 30 - ROUND((H25 / $H$2) * 30,0)), "") -> ▮▮▮▮▮▮▮▯▯▯▯▯▯▯▯▯▯▯▯▯▯▯▯▯▯▯▯▯▯▯ | J25: =IFERROR(ROUND(H25/F25, 1), "") -> 10.5 | K25: =IFERROR(ROUND(MIN(99, 94 * (0.8*MIN(1, J25/J$2) + 0.2*H25/H$2)),0), "") -> 73 | L25: Isak L | M25: =SUMIF(Spelarstatistik!A$2:A179, L25, Spelarstatistik!B$2:B179) -> 13 | N25: =SUMIF(Spelarstatistik!A$2:A179, L25, Spelarstatistik!C$2:C179) -> 11 | O25: =SUMIF(Spelarstatistik!A$2:A179, L25, Spelarstatistik!D$2:D179) -> 17 | P25: =SUMIF(Spelarstatistik!A$2:A179, L25, Spelarstatistik!E$2:E179) -> 27 | Q25: =COUNTIF(Spelarstatistik!A$2:A179, L25) -> 7 | R25: =SUMIF(Matcher!AC$5:AC179, L25, Matcher!AH$5:AH179) -> 0 | S25: =IF(L25 <> "", ROUND(M25 + N25 + 0.5 * O25 + 5 * Q25 + 0.5 * R25,0), "") -> 68
A26: =IFERROR(__xludf.DUMMYFUNCTION("""COMPUTED_VALUE"""),"Shoresh A") -> Shoresh A | B26: =IFERROR(__xludf.DUMMYFUNCTION("""COMPUTED_VALUE"""),6.0) -> 6 | C26: =IFERROR(__xludf.DUMMYFUNCTION("""COMPUTED_VALUE"""),8.0) -> 8 | D26: =IFERROR(__xludf.DUMMYFUNCTION("""COMPUTED_VALUE"""),15.0) -> 15 | E26: =IFERROR(__xludf.DUMMYFUNCTION("""COMPUTED_VALUE"""),8.0) -> 8 | F26: =IFERROR(__xludf.DUMMYFUNCTION("""COMPUTED_VALUE"""),4.0) -> 4 | G26: =IFERROR(__xludf.DUMMYFUNCTION("""COMPUTED_VALUE"""),0.0) -> 0 | H26: =IFERROR(__xludf.DUMMYFUNCTION("""COMPUTED_VALUE"""),42.0) -> 42 | I26: =IF(H26 <> "", REPT("▮", ROUND((H26 / $H$2) * 30,0)) & REPT("▯", 30 - ROUND((H26 / $H$2) * 30,0)), "") -> ▮▮▮▮▮▮▮▯▯▯▯▯▯▯▯▯▯▯▯▯▯▯▯▯▯▯▯▯▯▯ | J26: =IFERROR(ROUND(H26/F26, 1), "") -> 10.5 | K26: =IFERROR(ROUND(MIN(99, 94 * (0.8*MIN(1, J26/J$2) + 0.2*H26/H$2)),0), "") -> 73 | L26: Ivan N | M26: =SUMIF(Spelarstatistik!A$2:A179, L26, Spelarstatistik!B$2:B179) -> 27 | N26: =SUMIF(Spelarstatistik!A$2:A179, L26, Spelarstatistik!C$2:C179) -> 24 | O26: =SUMIF(Spelarstatistik!A$2:A179, L26, Spelarstatistik!D$2:D179) -> 35 | P26: =SUMIF(Spelarstatistik!A$2:A179, L26, Spelarstatistik!E$2:E179) -> 39 | Q26: =COUNTIF(Spelarstatistik!A$2:A179, L26) -> 12 | R26: =SUMIF(Matcher!AC$5:AC179, L26, Matcher!AH$5:AH179) -> 0 | S26: =IF(L26 <> "", ROUND(M26 + N26 + 0.5 * O26 + 5 * Q26 + 0.5 * R26,0), "") -> 129
